Workbook

Sheet 사용법
A1: 2026 위례 AI 코딩 챌린지 — 심사표 및 투표(좋아요) 합산 (사용법)
A2: 학생 투표(좋아요) 50점 + 업무팀 심사 50점 = 100점 · 엑셀이 자동으로 합산해요. 노란 칸만 입력하세요.
A3: 일정: 좋아요 투표 주간·업무팀 심사 11. 9.(월)~11. 13.(금) → 점수 합산 11. 16.(월)~11. 17.(화) → 결과 발표·시상 11. 18.(수)
A5: 단계 | B5: 시트 | C5: 할 일
A6: 1 | B6: 작품목록 | C6: 업무팀이 확인해 온라인 갤러리에 공개한 작품(블록·바이브)과 1~2학년 상상 부문 활동지를 한 줄에 하나씩 모두 입력해요(1차 심사 없음). 작품번호는 갤러리와 똑같이 블록코딩 B-01, 바이브코딩 V-01, 상상 S-01처럼 두 자리로 써요. 대표 학년반은 '4-2'처럼 목록에서 고르고, 2인 팀이면 팀원 학년반도 골라요(다른 반 가능). 예시 24개 행은 지우고 실제 작품으로 바꾸세요. (최대 100개)
A7: 2 | B7: 심사_블록바이브 / 심사_상상 | C7: A열에 작품번호를 쓰면 부문·작품 이름이 자동으로 나와요. 심사위원 3명이 항목별 점수를 입력하면 심사위원별 합계, 평균(50점 만점), 동점 기준 점수(제작 과정 평균 / 아이디어 독창성 평균)가 자동 계산돼요. 배점보다 큰 점수는 입력되지 않아요(데이터 유효성 검사).
A8: 3 | B8: 좋아요 수 (왼쪽 A~B열) | C8: 갤러리 결과 붙여넣기: 좋아요 투표가 끝나면(11. 13.(금)) 온라인 작품 갤러리의 결과 화면(또는 결과 시트)에서 '작품번호'와 '좋아요 수' 두 열만 복사해 A6 칸에 '값만 붙여넣기'해요. 제목 줄은 빼고, 순서는 상관없어요. 작품목록에 없는 번호나 두 번 들어간 번호는 C열에 빨간 글씨로 알려 줘요. 예시 16행은 지우고 붙여 넣으세요.
A9: 4 | B9: 좋아요 수 (오른쪽 I열) | C9: 상상 부문은 스티커 투표(1인 3장)이므로 작품별 스티커 수를 I열 노란 칸에 직접 입력해요. J열 '최종 좋아요 수'(상상은 스티커 수)와 K열 '부문 내 순위'가 자동으로 나와요.
A10: 5 | B10: 학급별참여율 (학생 수 입력) | C10: 학급 학생 수 입력: B열 노란 칸에 반별 학생 수를 입력해요. 없는 반은 비워 두면 순위에서 빠져요. 1~2학년은 담임 선생님이 알려 준 활동지 제출 학생 수를 F열에 쓰면, 작품목록에 빠짐없이 입력했는지 G열에서 '일치/작품목록 확인'으로 알려 줘요.
A11: 6 | B11: 학급별참여율 (참여율 확인) | C11: 참여율 확인: 참여 학생 수(작품목록의 대표 학년반 + 팀원 학년반), 참여율, 순위가 자동으로 계산되고 1~3위 반은 금·은·동색으로 표시돼요. 오른쪽 '참여율 순위 TOP 10' 표를 결과 발표(11. 18.(수)) 자료로 그대로 쓰세요. '학년반 확인 필요'가 0명이 아니면 작품목록의 학년반 칸을 고쳐요.
A12: 7 | B12: 최종결과 | C12: 심사 점수·좋아요 점수·총점·부문 내 순위·수상 추천을 확인해요. 수상 인원은 부문별 참가 작품 수의 10%(반올림, 최소 1명)로 자동 계산돼요. 필터(▼)로 부문별로 보고 '부문 내 순위' 기준으로 정렬하면 돼요.
A13: 8 | B13: 확인 및 결재 | C13: 점수 합산 기간(11. 16.(월)~11. 17.(화))에 동점·수상 추천 결과를 업무팀이 함께 확인하고, 최종 수상자는 학업성적관리규정의 교내상 비율 범위 안에서 확정해요. 결과 발표·방송 시상식은 11. 18.(수). 인쇄는 A4 가로로 설정되어 있어요.
A15: 색깔 안내
C16: 노란 칸 = 입력하는 칸 (작품 정보, 심사 점수, 좋아요 수 붙여넣기, 스티커 수, 학급 학생 수, 참가 작품 수)
C17: 회색 칸 = 자동 계산 칸 (수식이 들어 있으니 지우거나 고치지 마세요)
C18: 금색 줄(최종결과) = 최우수 추천 · 금색 줄(학급별참여율) = 참여율 1위 반
C19: 하늘색 줄(최종결과) = 우수 추천
C20: 연두색 줄(최종결과) = 장려 추천
C21: 은색 줄(학급별참여율) = 참여율 2위 반
C22: 동색 줄(학급별참여율) = 참여율 3위 반
C23: 빨간 글씨(좋아요 수 C열, 학급별참여율 G열) = 확인이 필요한 줄 (작품목록에 없는 번호, 중복 번호, 학생 수 미입력 등)
A25: 계산 규칙
B26: 심사 점수(50) | C26: 심사위원 3명 합계의 평균. 블록·바이브: 교과 연계성 15 + 학습 도움 정도 15 + 제작 과정 15 + 창의성 5 / 상상: 교과 연계성 15 + 아이디어 독창성 20 + 표현력 15. 입력된 심사위원 수만큼만 평균해요.
B27: 좋아요 점수(50) | C27: (작품 좋아요 수 ÷ 같은 부문 최다 좋아요 수) × 50, 소수 첫째 자리 반올림. 예) 좋아요 42개, 부문 최다 60개 → 42 ÷ 60 × 50 = 35점. 블록·바이브는 온라인 갤러리 좋아요(학생 1명이 작품마다 1번, 개수 제한 없음), 상상은 스티커 수(1인 3장)로 같은 식을 써요.
B28: 총점(100) | C28: 심사 점수 + 좋아요 점수 (소수 둘째 자리 반올림). 인기가 한쪽으로 쏠려도 업무팀 심사 50점이 보완해요.
B29: 동점 처리 | C29: 총점이 같으면 블록·바이브는 '제작 과정' 평균이, 상상은 '아이디어 독창성' 평균이 높은 작품이 앞 순위. (정렬 기준 = 총점 + 동점 기준 점수 ÷ 10000 — 총점 차이를 뒤집지 않는 아주 작은 값) 그래도 같으면 같은 순위로 표시되니 업무팀이 협의해요.
B30: 수상 인원 | C30: 부문별 참가 작품 수 × 10%(최종결과 시트 노란 칸에서 비율 변경 가능), 반올림, 최소 1명. 1차 심사 없이 확인된 작품은 모두 작품목록에 들어가므로, '참가 작품 수'를 비워 두면 작품목록의 작품 수로 계산해요.
B31: 수상 추천 | C31: 수상 인원 안에서 1위 = 최우수, 2~3위 = 우수, 4위부터 = 장려. (예: 수상 인원 5명 → 최우수 1, 우수 2, 장려 2)
B32: 학급별 참여율 | C32: 참여 학생 수 = 작품목록에서 대표 학년반이 그 반인 작품 수 + 팀원 학년반이 그 반인 작품 수 (2인 팀은 두 학생 모두 각자 반으로 세고, 1~2학년 상상 활동지도 포함). 참여율 = 참여 학생 수 ÷ 학급 학생 수. 순위는 참여율이 높은 순, 참여율이 같으면 참여 학생 수가 많은 반이 위, 그래도 같으면 같은 순위.
B33: 번호·학년반 주의 | C33: 작품번호는 갤러리와 똑같이 'B-01'처럼 두 자리로 써야 좋아요 수가 연결돼요. 학년반은 '4-2' 형식으로만(목록 선택) — '4학년 2반'처럼 쓰면 참여율에 세지지 않아요. 학년반 칸은 날짜(4월 2일)로 바뀌지 않도록 텍스트 서식이 걸려 있어요.

Sheet 작품목록
A1: 작품목록 (확인 후 공개된 전체 작품 + 상상 부문 활동지)
A2: 1차 심사 없이 확인된 작품은 모두 입력해요 · 작품번호: 블록코딩 B-01~, 바이브코딩 V-01~, 상상 S-01~ · 학년반은 4-2처럼(목록 선택) · 최대 100개 · 예시 행은 지우고 입력하세요.
A3: 작품번호 | B3: 부문 | C3: 대표 학년반 (예: 4-2) | D3: 팀원 학년반 (2인 팀일 때, 다른 반 가능) | E3: 이름(팀) | F3: 교과·단원 | G3: 작품 이름 | H3: 링크
A4: B-01 | B4: 블록 | C4: 3-2 | E4: 최○○ | F4: 수학 「곱셈」 | G4: 구구단 우주선 | H4: https://example.com/wirye-ai/B-01
A5: B-02 | B5: 블록 | C5: 6-4 | E5: 정○○ | F5: 영어 「What's your favorite subject?」 | G5: 영어 단어 짝 맞추기 | H5: https://example.com/wirye-ai/B-02
A6: B-03 | B6: 블록 | C6: 4-1 | E6: 윤○○ | F6: 과학 「식물의 한살이」 | G6: 씨앗 키우기 순서 게임 | H6: https://example.com/wirye-ai/B-03
A7: B-04 | B7: 블록 | C7: 5-3 | D7: 5-2 | E7: 강○○·조○○ | F7: 수학 「약수와 배수」 | G7: 배수 사냥꾼 | H7: https://example.com/wirye-ai/B-04
A8: B-05 | B8: 블록 | C8: 3-5 | E8: 임○○ | F8: 국어 「낱말을 분류해요」 | G8: 낱말 바구니 분류하기 | H8: https://example.com/wirye-ai/B-05
A9: B-06 | B9: 블록 | C9: 6-2 | E9: 오○○ | F9: 과학 「태양계와 별」 | G9: 행성 순서 맞히기 | H9: https://example.com/wirye-ai/B-06
A10: B-07 | B10: 블록 | C10: 4-6 | E10: 서○○ | F10: 사회 「지역의 위치와 특성」 | G10: 우리 지역 지도 탐험 | H10: https://example.com/wirye-ai/B-07
A11: B-08 | B11: 블록 | C11: 5-2 | E11: 신○○ | F11: 수학 「분수의 덧셈과 뺄셈」 | G11: 분수 피자 가게 | H11: https://example.com/wirye-ai/B-08
A12: V-01 | B12: 바이브 | C12: 4-3 | E12: 김○○ | F12: 수학 「각도」 | G12: 각도 탐정 게임 | H12: https://example.com/wirye-ai/V-01
A13: V-02 | B13: 바이브 | C13: 5-1 | D13: 5-1 | E13: 이○○·박○○ | F13: 사회 「국토와 우리 생활」 | G13: 우리나라 시·도 퀴즈 | H13: https://example.com/wirye-ai/V-02
A14: V-03 | B14: 바이브 | C14: 6-1 | E14: 홍○○ | F14: 과학 「산과 염기」 | G14: 지시약 색깔 실험실 | H14: https://example.com/wirye-ai/V-03
A15: V-04 | B15: 바이브 | C15: 3-4 | E15: 문○○ | F15: 국어 「중심 생각을 찾아요」 | G15: 중심 문장 찾기 놀이 | H15: https://example.com/wirye-ai/V-04
A16: V-05 | B16: 바이브 | C16: 5-4 | E16: 양○○ | F16: 영어 「How much is it?」 | G16: 영어 시장 놀이 | H16: https://example.com/wirye-ai/V-05
A17: V-06 | B17: 바이브 | C17: 4-2 | D17: 4-2 | E17: 배○○·백○○ | F17: 과학 「물의 상태 변화」 | G17: 얼음·물·수증기 변신 퀴즈 | H17: https://example.com/wirye-ai/V-06
A18: V-07 | B18: 바이브 | C18: 6-3 | E18: 송○○ | F18: 수학 「비와 비율」 | G18: 비율 요리사 | H18: https://example.com/wirye-ai/V-07
A19: V-08 | B19: 바이브 | C19: 3-1 | E19: 유○○ | F19: 사회 「우리 고장의 모습」 | G19: 고장 지도 기호 카드 | H19: https://example.com/wirye-ai/V-08
A20: S-01 | B20: 상상 | C20: 2-1 | E20: 한○○ | F20: 국어 「받침이 있는 낱말」 | G20: 받침 친구 로봇 '받침이' | H20: (실물 활동지 전시)
A21: S-02 | B21: 상상 | C21: 1-3 | E21: 장○○ | F21: 수학 「덧셈과 뺄셈」 | G21: 덧셈 요정 '더하리' | H21: (실물 활동지 전시)
A22: S-03 | B22: 상상 | C22: 2-4 | E22: 권○○ | F22: 통합 「가을」 | G22: 낙엽 이름 알려 주는 다람쥐 AI | H22: (실물 활동지 전시)
A23: S-04 | B23: 상상 | C23: 1-1 | E23: 황○○ | F23: 국어 「글자를 만들어요」 | G23: 자음 모음 블록 친구 | H23: (실물 활동지 전시)
A24: S-05 | B24: 상상 | C24: 2-2 | E24: 안○○ | F24: 수학 「시각과 시간」 | G24: 시계 읽어 주는 부엉이 | H24: (실물 활동지 전시)
A25: S-06 | B25: 상상 | C25: 1-5 | E25: 전○○ | F25: 통합 「학교」 | G25: 학교 길 안내 로봇 '길동이' | H25: (실물 활동지 전시)
A26: S-07 | B26: 상상 | C26: 2-3 | E26: 고○○ | F26: 수학 「곱셈구구」 | G26: 구구단 노래 상자 | H26: (실물 활동지 전시)
A27: S-08 | B27: 상상 | C27: 1-2 | E27: 류○○ | F27: 국어 「바른 자세로 읽어요」 | G27: 또박또박 읽기 마이크 | H27: (실물 활동지 전시)

Sheet 심사_블록바이브
A1: 업무팀 심사표 — 블록코딩 · 바이브코딩 (50점)
A2: A열에 작품번호를 입력하면 부문·작품 이름이 자동으로 나와요. 노란 칸에 심사위원별 점수를 입력하세요(배점 초과 입력 불가).
A3: 작품번호 | B3: 부문 | C3: 작품 이름 | D3: 심사위원 1 | I3: 심사위원 2 | N3: 심사위원 3 | S3: 심사 점수 평균(50) | T3: 제작 과정 평균(동점 기준)
D4: 교과 연계성 (15) | E4: 학습 도움 (15) | F4: 제작 과정 (15) | G4: 창의성 (5) | H4: 합계 (50) | I4: 교과 연계성 (15) | J4: 학습 도움 (15) | K4: 제작 과정 (15) | L4: 창의성 (5) | M4: 합계 (50) | N4: 교과 연계성 (15) | O4: 학습 도움 (15) | P4: 제작 과정 (15) | Q4: 창의성 (5) | R4: 합계 (50)
A5: B-01 | B5: =IF(A5="","",IFERROR(INDEX(작품목록!$B$4:$B$103,MATCH(A5,작품목록!$A$4:$A$103,0)),"번호 확인")) -> 블록 | C5: =IF(A5="","",IFERROR(INDEX(작품목록!$G$4:$G$103,MATCH(A5,작품목록!$A$4:$A$103,0)),"작품목록에 없음")) -> 구구단 우주선 | D5: 13 | E5: 14 | F5: 14 | G5: 5 | H5: =IF(COUNT(D5:G5)=0,"",SUM(D5:G5)) -> 46 | I5: 13 | J5: 13 | K5: 14 | L5: 5 | M5: =IF(COUNT(I5:L5)=0,"",SUM(I5:L5)) -> 45 | N5: 14 | O5: 14 | P5: 14 | Q5: 5 | R5: =IF(COUNT(N5:Q5)=0,"",SUM(N5:Q5)) -> 47 | S5: =IF(COUNT(H5,M5,R5)=0,"",ROUND(AVERAGE(H5,M5,R5),2)) -> 46 | T5: =IF(COUNT(F5,K5,P5)=0,"",ROUND(AVERAGE(F5,K5,P5),2)) -> 14
A6: B-02 | B6: =IF(A6="","",IFERROR(INDEX(작품목록!$B$4:$B$103,MATCH(A6,작품목록!$A$4:$A$103,0)),"번호 확인")) -> 블록 | C6: =IF(A6="","",IFERROR(INDEX(작품목록!$G$4:$G$103,MATCH(A6,작품목록!$A$4:$A$103,0)),"작품목록에 없음")) -> 영어 단어 짝 맞추기 | D6: 13 | E6: 12 | F6: 11 | G6: 4 | H6: =IF(COUNT(D6:G6)=0,"",SUM(D6:G6)) -> 40 | I6: 11 | J6: 13 | K6: 12 | L6: 4 | M6: =IF(COUNT(I6:L6)=0,"",SUM(I6:L6)) -> 40 | N6: 12 | O6: 12 | P6: 11 | Q6: 4 | R6: =IF(COUNT(N6:Q6)=0,"",SUM(N6:Q6)) -> 39 | S6: =IF(COUNT(H6,M6,R6)=0,"",ROUND(AVERAGE(H6,M6,R6),2)) -> 39.67 | T6: =IF(COUNT(F6,K6,P6)=0,"",ROUND(AVERAGE(F6,K6,P6),2)) -> 11.33
A7: B-03 | B7: =IF(A7="","",IFERROR(INDEX(작품목록!$B$4:$B$103,MATCH(A7,작품목록!$A$4:$A$103,0)),"번호 확인")) -> 블록 | C7: =IF(A7="","",IFERROR(INDEX(작품목록!$G$4:$G$103,MATCH(A7,작품목록!$A$4:$A$103,0)),"작품목록에 없음")) -> 씨앗 키우기 순서 게임 | D7: 12 | E7: 12 | F7: 11 | G7: 4 | H7: =IF(COUNT(D7:G7)=0,"",SUM(D7:G7)) -> 39 | I7: 11 | J7: 9 | K7: 10 | L7: 4 | M7: =IF(COUNT(I7:L7)=0,"",SUM(I7:L7)) -> 34 | N7: 10 | O7: 10 | P7: 11 | Q7: 4 | R7: =IF(COUNT(N7:Q7)=0,"",SUM(N7:Q7)) -> 35 | S7: =IF(COUNT(H7,M7,R7)=0,"",ROUND(AVERAGE(H7,M7,R7),2)) -> 36 | T7: =IF(COUNT(F7,K7,P7)=0,"",ROUND(AVERAGE(F7,K7,P7),2)) -> 10.67
A8: B-04 | B8: =IF(A8="","",IFERROR(INDEX(작품목록!$B$4:$B$103,MATCH(A8,작품목록!$A$4:$A$103,0)),"번호 확인")) -> 블록 | C8: =IF(A8="","",IFERROR(INDEX(작품목록!$G$4:$G$103,MATCH(A8,작품목록!$A$4:$A$103,0)),"작품목록에 없음")) -> 배수 사냥꾼 | D8: 13 | E8: 12 | F8: 13 | G8: 4 | H8: =IF(COUNT(D8:G8)=0,"",SUM(D8:G8)) -> 42 | I8: 13 | J8: 13 | K8: 13 | L8: 4 | M8: =IF(COUNT(I8:L8)=0,"",SUM(I8:L8)) -> 43 | N8: 12 | O8: 13 | P8: 14 | Q8: 4 | R8: =IF(COUNT(N8:Q8)=0,"",SUM(N8:Q8)) -> 43 | S8: =IF(COUNT(H8,M8,R8)=0,"",ROUND(AVERAGE(H8,M8,R8),2)) -> 42.67 | T8: =IF(COUNT(F8,K8,P8)=0,"",ROUND(AVERAGE(F8,K8,P8),2)) -> 13.33
A9: B-05 | B9: =IF(A9="","",IFERROR(INDEX(작품목록!$B$4:$B$103,MATCH(A9,작품목록!$A$4:$A$103,0)),"번호 확인")) -> 블록 | C9: =IF(A9="","",IFERROR(INDEX(작품목록!$G$4:$G$103,MATCH(A9,작품목록!$A$4:$A$103,0)),"작품목록에 없음")) -> 낱말 바구니 분류하기 | D9: 9 | E9: 10 | F9: 9 | G9: 3 | H9: =IF(COUNT(D9:G9)=0,"",SUM(D9:G9)) -> 31 | I9: 10 | J9: 9 | K9: 9 | L9: 3 | M9: =IF(COUNT(I9:L9)=0,"",SUM(I9:L9)) -> 31 | N9: 9 | O9: 8 | P9: 8 | Q9: 3 | R9: =IF(COUNT(N9:Q9)=0,"",SUM(N9:Q9)) -> 28 | S9: =IF(COUNT(H9,M9,R9)=0,"",ROUND(AVERAGE(H9,M9,R9),2)) -> 30 | T9: =IF(COUNT(F9,K9,P9)=0,"",ROUND(AVERAGE(F9,K9,P9),2)) -> 8.67
A10: B-06 | B10: =IF(A10="","",IFERROR(INDEX(작품목록!$B$4:$B$103,MATCH(A10,작품목록!$A$4:$A$103,0)),"번호 확인")) -> 블록 | C10: =IF(A10="","",IFERROR(INDEX(작품목록!$G$4:$G$103,MATCH(A10,작품목록!$A$4:$A$103,0)),"작품목록에 없음")) -> 행성 순서 맞히기 | D10: 13 | E10: 11 | F10: 12 | G10: 4 | H10: =IF(COUNT(D10:G10)=0,"",SUM(D10:G10)) -> 40 | I10: 12 | J10: 11 | K10: 13 | L10: 4 | M10: =IF(COUNT(I10:L10)=0,"",SUM(I10:L10)) -> 40 | N10: 12 | O10: 12 | P10: 13 | Q10: 4 | R10: =IF(COUNT(N10:Q10)=0,"",SUM(N10:Q10)) -> 41 | S10: =IF(COUNT(H10,M10,R10)=0,"",ROUND(AVERAGE(H10,M10,R10),2)) -> 40.33 | T10: =IF(COUNT(F10,K10,P10)=0,"",ROUND(AVERAGE(F10,K10,P10),2)) -> 12.67
A11: B-07 | B11: =IF(A11="","",IFERROR(INDEX(작품목록!$B$4:$B$103,MATCH(A11,작품목록!$A$4:$A$103,0)),"번호 확인")) -> 블록 | C11: =IF(A11="","",IFERROR(INDEX(작품목록!$G$4:$G$103,MATCH(A11,작품목록!$A$4:$A$103,0)),"작품목록에 없음")) -> 우리 지역 지도 탐험 | D11: 10 | E11: 10 | F11: 10 | G11: 3 | H11: =IF(COUNT(D11:G11)=0,"",SUM(D11:G11)) -> 33 | I11: 11 | J11: 10 | K11: 10 | L11: 4 | M11: =IF(COUNT(I11:L11)=0,"",SUM(I11:L11)) -> 35 | N11: 10 | O11: 9 | P11: 9 | Q11: 3 | R11: =IF(COUNT(N11:Q11)=0,"",SUM(N11:Q11)) -> 31 | S11: =IF(COUNT(H11,M11,R11)=0,"",ROUND(AVERAGE(H11,M11,R11),2)) -> 33 | T11: =IF(COUNT(F11,K11,P11)=0,"",ROUND(AVERAGE(F11,K11,P11),2)) -> 9.67
A12: B-08 | B12: =IF(A12="","",IFERROR(INDEX(작품목록!$B$4:$B$103,MATCH(A12,작품목록!$A$4:$A$103,0)),"번호 확인")) -> 블록 | C12: =IF(A12="","",IFERROR(INDEX(작품목록!$G$4:$G$103,MATCH(A12,작품목록!$A$4:$A$103,0)),"작품목록에 없음")) -> 분수 피자 가게 | D12: 13 | E12: 13 | F12: 12 | G12: 4 | H12: =IF(COUNT(D12:G12)=0,"",SUM(D12:G12)) -> 42 | I12: 13 | J12: 14 | K12: 12 | L12: 4 | M12: =IF(COUNT(I12:L12)=0,"",SUM(I12:L12)) -> 43 | N12: 13 | O12: 13 | P12: 13 | Q12: 4 | R12: =IF(COUNT(N12:Q12)=0,"",SUM(N12:Q12)) -> 43 | S12: =IF(COUNT(H12,M12,R12)=0,"",ROUND(AVERAGE(H12,M12,R12),2)) -> 42.67 | T12: =IF(COUNT(F12,K12,P12)=0,"",ROUND(AVERAGE(F12,K12,P12),2)) -> 12.33
A13: V-01 | B13: =IF(A13="","",IFERROR(INDEX(작품목록!$B$4:$B$103,MATCH(A13,작품목록!$A$4:$A$103,0)),"번호 확인")) -> 바이브 | C13: =IF(A13="","",IFERROR(INDEX(작품목록!$G$4:$G$103,MATCH(A13,작품목록!$A$4:$A$103,0)),"작품목록에 없음")) -> 각도 탐정 게임 | D13: 14 | E13: 14 | F13: 13 | G13: 5 | H13: =IF(COUNT(D13:G13)=0,"",SUM(D13:G13)) -> 46 | I13: 13 | J13: 14 | K13: 14 | L13: 5 | M13: =IF(COUNT(I13:L13)=0,"",SUM(I13:L13)) -> 46 | N13: 13 | O13: 15 | P13: 15 | Q13: 5 | R13: =IF(COUNT(N13:Q13)=0,"",SUM(N13:Q13)) -> 48 | S13: =IF(COUNT(H13,M13,R13)=0,"",ROUND(AVERAGE(H13,M13,R13),2)) -> 46.67 | T13: =IF(COUNT(F13,K13,P13)=0,"",ROUND(AVERAGE(F13,K13,P13),2)) -> 14
A14: V-02 | B14: =IF(A14="","",IFERROR(INDEX(작품목록!$B$4:$B$103,MATCH(A14,작품목록!$A$4:$A$103,0)),"번호 확인")) -> 바이브 | C14: =IF(A14="","",IFERROR(INDEX(작품목록!$G$4:$G$103,MATCH(A14,작품목록!$A$4:$A$103,0)),"작품목록에 없음")) -> 우리나라 시·도 퀴즈 | D14: 13 | E14: 12 | F14: 12 | G14: 4 | H14: =IF(COUNT(D14:G14)=0,"",SUM(D14:G14)) -> 41 | I14: 12 | J14: 13 | K14: 12 | L14: 4 | M14: =IF(COUNT(I14:L14)=0,"",SUM(I14:L14)) -> 41 | N14: 11 | O14: 11 | P14: 13 | Q14: 5 | R14: =IF(COUNT(N14:Q14)=0,"",SUM(N14:Q14)) -> 40 | S14: =IF(COUNT(H14,M14,R14)=0,"",ROUND(AVERAGE(H14,M14,R14),2)) -> 40.67 | T14: =IF(COUNT(F14,K14,P14)=0,"",ROUND(AVERAGE(F14,K14,P14),2)) -> 12.33
A15: V-03 | B15: =IF(A15="","",IFERROR(INDEX(작품목록!$B$4:$B$103,MATCH(A15,작품목록!$A$4:$A$103,0)),"번호 확인")) -> 바이브 | C15: =IF(A15="","",IFERROR(INDEX(작품목록!$G$4:$G$103,MATCH(A15,작품목록!$A$4:$A$103,0)),"작품목록에 없음")) -> 지시약 색깔 실험실 | D15: 10 | E15: 12 | F15: 11 | G15: 4 | H15: =IF(COUNT(D15:G15)=0,"",SUM(D15:G15)) -> 37 | I15: 12 | J15: 12 | K15: 12 | L15: 4 | M15: =IF(COUNT(I15:L15)=0,"",SUM(I15:L15)) -> 40 | N15: 11 | O15: 11 | P15: 12 | Q15: 4 | R15: =IF(COUNT(N15:Q15)=0,"",SUM(N15:Q15)) -> 38 | S15: =IF(COUNT(H15,M15,R15)=0,"",ROUND(AVERAGE(H15,M15,R15),2)) -> 38.33 | T15: =IF(COUNT(F15,K15,P15)=0,"",ROUND(AVERAGE(F15,K15,P15),2)) -> 11.67
A16: V-04 | B16: =IF(A16="","",IFERROR(INDEX(작품목록!$B$4:$B$103,MATCH(A16,작품목록!$A$4:$A$103,0)),"번호 확인")) -> 바이브 | C16: =IF(A16="","",IFERROR(INDEX(작품목록!$G$4:$G$103,MATCH(A16,작품목록!$A$4:$A$103,0)),"작품목록에 없음")) -> 중심 문장 찾기 놀이 | D16: 11 | E16: 10 | F16: 10 | G16: 3 | H16: =IF(COUNT(D16:G16)=0,"",SUM(D16:G16)) -> 34 | I16: 9 | J16: 10 | K16: 11 | L16: 4 | M16: =IF(COUNT(I16:L16)=0,"",SUM(I16:L16)) -> 34 | N16: 10 | O16: 9 | P16: 10 | Q16: 4 | R16: =IF(COUNT(N16:Q16)=0,"",SUM(N16:Q16)) -> 33 | S16: =IF(COUNT(H16,M16,R16)=0,"",ROUND(AVERAGE(H16,M16,R16),2)) -> 33.67 | T16: =IF(COUNT(F16,K16,P16)=0,"",ROUND(AVERAGE(F16,K16,P16),2)) -> 10.33
... A20: V-08 | B20: =IF(A20="","",IFERROR(INDEX(작품목록!$B$4:$B$103,MATCH(A20,작품목록!$A$4:$A$103,0)),"번호 확인")) -> 바이브 | C20: =IF(A20="","",IFERROR(INDEX(작품목록!$G$4:$G$103,MATCH(A20,작품목록!$A$4:$A$103,0)),"작품목록에 없음")) -> 고장 지도 기호 카드 | D20: 9 | E20: 10 | F20: 8 | G20: 3 | H20: =IF(COUNT(D20:G20)=0,"",SUM(D20:G20)) -> 30 | I20: 10 | J20: 8 | K20: 9 | L20: 3 | M20: =IF(COUNT(I20:L20)=0,"",SUM(I20:L20)) -> 30 | N20: 9 | O20: 10 | P20: 8 | Q20: 3 | R20: =IF(COUNT(N20:Q20)=0,"",SUM(N20:Q20)) -> 30 | S20: =IF(COUNT(H20,M20,R20)=0,"",ROUND(AVERAGE(H20,M20,R20),2)) -> 30 | T20: =IF(COUNT(F20,K20,P20)=0,"",ROUND(AVERAGE(F20,K20,P20),2)) -> 8.33
B21: =IF(A21="","",IFERROR(INDEX(작품목록!$B$4:$B$103,MATCH(A21,작품목록!$A$4:$A$103,0)),"번호 확인")) | C21: =IF(A21="","",IFERROR(INDEX(작품목록!$G$4:$G$103,MATCH(A21,작품목록!$A$4:$A$103,0)),"작품목록에 없음")) | H21: =IF(COUNT(D21:G21)=0,"",SUM(D21:G21)) | M21: =IF(COUNT(I21:L21)=0,"",SUM(I21:L21)) | R21: =IF(COUNT(N21:Q21)=0,"",SUM(N21:Q21)) | S21: =IF(COUNT(H21,M21,R21)=0,"",ROUND(AVERAGE(H21,M21,R21),2)) | T21: =IF(COUNT(F21,K21,P21)=0,"",ROUND(AVERAGE(F21,K21,P21),2))
B22: =IF(A22="","",IFERROR(INDEX(작품목록!$B$4:$B$103,MATCH(A22,작품목록!$A$4:$A$103,0)),"번호 확인")) | C22: =IF(A22="","",IFERROR(INDEX(작품목록!$G$4:$G$103,MATCH(A22,작품목록!$A$4:$A$103,0)),"작품목록에 없음")) | H22: =IF(COUNT(D22:G22)=0,"",SUM(D22:G22)) | M22: =IF(COUNT(I22:L22)=0,"",SUM(I22:L22)) | R22: =IF(COUNT(N22:Q22)=0,"",SUM(N22:Q22)) | S22: =IF(COUNT(H22,M22,R22)=0,"",ROUND(AVERAGE(H22,M22,R22),2)) | T22: =IF(COUNT(F22,K22,P22)=0,"",ROUND(AVERAGE(F22,K22,P22),2))
B23: =IF(A23="","",IFERROR(INDEX(작품목록!$B$4:$B$103,MATCH(A23,작품목록!$A$4:$A$103,0)),"번호 확인")) | C23: =IF(A23="","",IFERROR(INDEX(작품목록!$G$4:$G$103,MATCH(A23,작품목록!$A$4:$A$103,0)),"작품목록에 없음")) | H23: =IF(COUNT(D23:G23)=0,"",SUM(D23:G23)) | M23: =IF(COUNT(I23:L23)=0,"",SUM(I23:L23)) | R23: =IF(COUNT(N23:Q23)=0,"",SUM(N23:Q23)) | S23: =IF(COUNT(H23,M23,R23)=0,"",ROUND(AVERAGE(H23,M23,R23),2)) | T23: =IF(COUNT(F23,K23,P23)=0,"",ROUND(AVERAGE(F23,K23,P23),2))
B24: =IF(A24="","",IFERROR(INDEX(작품목록!$B$4:$B$103,MATCH(A24,작품목록!$A$4:$A$103,0)),"번호 확인")) | C24: =IF(A24="","",IFERROR(INDEX(작품목록!$G$4:$G$103,MATCH(A24,작품목록!$A$4:$A$103,0)),"작품목록에 없음")) | H24: =IF(COUNT(D24:G24)=0,"",SUM(D24:G24)) | M24: =IF(COUNT(I24:L24)=0,"",SUM(I24:L24)) | R24: =IF(COUNT(N24:Q24)=0,"",SUM(N24:Q24)) | S24: =IF(COUNT(H24,M24,R24)=0,"",ROUND(AVERAGE(H24,M24,R24),2)) | T24: =IF(COUNT(F24,K24,P24)=0,"",ROUND(AVERAGE(F24,K24,P24),2))
B25: =IF(A25="","",IFERROR(INDEX(작품목록!$B$4:$B$103,MATCH(A25,작품목록!$A$4:$A$103,0)),"번호 확인")) | C25: =IF(A25="","",IFERROR(INDEX(작품목록!$G$4:$G$103,MATCH(A25,작품목록!$A$4:$A$103,0)),"작품목록에 없음")) | H25: =IF(COUNT(D25:G25)=0,"",SUM(D25:G25)) | M25: =IF(COUNT(I25:L25)=0,"",SUM(I25:L25)) | R25: =IF(COUNT(N25:Q25)=0,"",SUM(N25:Q25)) | S25: =IF(COUNT(H25,M25,R25)=0,"",ROUND(AVERAGE(H25,M25,R25),2)) | T25: =IF(COUNT(F25,K25,P25)=0,"",ROUND(AVERAGE(F25,K25,P25),2))
B26: =IF(A26="","",IFERROR(INDEX(작품목록!$B$4:$B$103,MATCH(A26,작품목록!$A$4:$A$103,0)),"번호 확인")) | C26: =IF(A26="","",IFERROR(INDEX(작품목록!$G$4:$G$103,MATCH(A26,작품목록!$A$4:$A$103,0)),"작품목록에 없음")) | H26: =IF(COUNT(D26:G26)=0,"",SUM(D26:G26)) | M26: =IF(COUNT(I26:L26)=0,"",SUM(I26:L26)) | R26: =IF(COUNT(N26:Q26)=0,"",SUM(N26:Q26)) | S26: =IF(COUNT(H26,M26,R26)=0,"",ROUND(AVERAGE(H26,M26,R26),2)) | T26: =IF(COUNT(F26,K26,P26)=0,"",ROUND(AVERAGE(F26,K26,P26),2))
B27: =IF(A27="","",IFERROR(INDEX(작품목록!$B$4:$B$103,MATCH(A27,작품목록!$A$4:$A$103,0)),"번호 확인")) | C27: =IF(A27="","",IFERROR(INDEX(작품목록!$G$4:$G$103,MATCH(A27,작품목록!$A$4:$A$103,0)),"작품목록에 없음")) | H27: =IF(COUNT(D27:G27)=0,"",SUM(D27:G27)) | M27: =IF(COUNT(I27:L27)=0,"",SUM(I27:L27)) | R27: =IF(COUNT(N27:Q27)=0,"",SUM(N27:Q27)) | S27: =IF(COUNT(H27,M27,R27)=0,"",ROUND(AVERAGE(H27,M27,R27),2)) | T27: =IF(COUNT(F27,K27,P27)=0,"",ROUND(AVERAGE(F27,K27,P27),2))
B28: =IF(A28="","",IFERROR(INDEX(작품목록!$B$4:$B$103,MATCH(A28,작품목록!$A$4:$A$103,0)),"번호 확인")) | C28: =IF(A28="","",IFERROR(INDEX(작품목록!$G$4:$G$103,MATCH(A28,작품목록!$A$4:$A$103,0)),"작품목록에 없음")) | H28: =IF(COUNT(D28:G28)=0,"",SUM(D28:G28)) | M28: =IF(COUNT(I28:L28)=0,"",SUM(I28:L28)) | R28: =IF(COUNT(N28:Q28)=0,"",SUM(N28:Q28)) | S28: =IF(COUNT(H28,M28,R28)=0,"",ROUND(AVERAGE(H28,M28,R28),2)) | T28: =IF(COUNT(F28,K28,P28)=0,"",ROUND(AVERAGE(F28,K28,P28),2))
B29: =IF(A29="","",IFERROR(INDEX(작품목록!$B$4:$B$103,MATCH(A29,작품목록!$A$4:$A$103,0)),"번호 확인")) | C29: =IF(A29="","",IFERROR(INDEX(작품목록!$G$4:$G$103,MATCH(A29,작품목록!$A$4:$A$103,0)),"작품목록에 없음")) | H29: =IF(COUNT(D29:G29)=0,"",SUM(D29:G29)) | M29: =IF(COUNT(I29:L29)=0,"",SUM(I29:L29)) | R29: =IF(COUNT(N29:Q29)=0,"",SUM(N29:Q29)) | S29: =IF(COUNT(H29,M29,R29)=0,"",ROUND(AVERAGE(H29,M29,R29),2)) | T29: =IF(COUNT(F29,K29,P29)=0,"",ROUND(AVERAGE(F29,K29,P29),2))
B30: =IF(A30="","",IFERROR(INDEX(작품목록!$B$4:$B$103,MATCH(A30,작품목록!$A$4:$A$103,0)),"번호 확인")) | C30: =IF(A30="","",IFERROR(INDEX(작품목록!$G$4:$G$103,MATCH(A30,작품목록!$A$4:$A$103,0)),"작품목록에 없음")) | H30: =IF(COUNT(D30:G30)=0,"",SUM(D30:G30)) | M30: =IF(COUNT(I30:L30)=0,"",SUM(I30:L30)) | R30: =IF(COUNT(N30:Q30)=0,"",SUM(N30:Q30)) | S30: =IF(COUNT(H30,M30,R30)=0,"",ROUND(AVERAGE(H30,M30,R30),2)) | T30: =IF(COUNT(F30,K30,P30)=0,"",ROUND(AVERAGE(F30,K30,P30),2))
B31: =IF(A31="","",IFERROR(INDEX(작품목록!$B$4:$B$103,MATCH(A31,작품목록!$A$4:$A$103,0)),"번호 확인")) | C31: =IF(A31="","",IFERROR(INDEX(작품목록!$G$4:$G$103,MATCH(A31,작품목록!$A$4:$A$103,0)),"작품목록에 없음")) | H31: =IF(COUNT(D31:G31)=0,"",SUM(D31:G31)) | M31: =IF(COUNT(I31:L31)=0,"",SUM(I31:L31)) | R31: =IF(COUNT(N31:Q31)=0,"",SUM(N31:Q31)) | S31: =IF(COUNT(H31,M31,R31)=0,"",ROUND(AVERAGE(H31,M31,R31),2)) | T31: =IF(COUNT(F31,K31,P31)=0,"",ROUND(AVERAGE(F31,K31,P31),2))
B32: =IF(A32="","",IFERROR(INDEX(작품목록!$B$4:$B$103,MATCH(A32,작품목록!$A$4:$A$103,0)),"번호 확인")) | C32: =IF(A32="","",IFERROR(INDEX(작품목록!$G$4:$G$103,MATCH(A32,작품목록!$A$4:$A$103,0)),"작품목록에 없음")) | H32: =IF(COUNT(D32:G32)=0,"",SUM(D32:G32)) | M32: =IF(COUNT(I32:L32)=0,"",SUM(I32:L32)) | R32: =IF(COUNT(N32:Q32)=0,"",SUM(N32:Q32)) | S32: =IF(COUNT(H32,M32,R32)=0,"",ROUND(AVERAGE(H32,M32,R32),2)) | T32: =IF(COUNT(F32,K32,P32)=0,"",ROUND(AVERAGE(F32,K32,P32),2))
... B104: =IF(A104="","",IFERROR(INDEX(작품목록!$B$4:$B$103,MATCH(A104,작품목록!$A$4:$A$103,0)),"번호 확인")) | C104: =IF(A104="","",IFERROR(INDEX(작품목록!$G$4:$G$103,MATCH(A104,작품목록!$A$4:$A$103,0)),"작품목록에 없음")) | H104: =IF(COUNT(D104:G104)=0,"",SUM(D104:G104)) | M104: =IF(COUNT(I104:L104)=0,"",SUM(I104:L104)) | R104: =IF(COUNT(N104:Q104)=0,"",SUM(N104:Q104)) | S104: =IF(COUNT(H104,M104,R104)=0,"",ROUND(AVERAGE(H104,M104,R104),2)) | T104: =IF(COUNT(F104,K104,P104)=0,"",ROUND(AVERAGE(F104,K104,P104),2))

Sheet 심사_상상
A1: 업무팀 심사표 — 상상 부문 (50점)
A2: A열에 작품번호를 입력하면 부문·작품 이름이 자동으로 나와요. 노란 칸에 심사위원별 점수를 입력하세요(배점 초과 입력 불가).
A3: 작품번호 | B3: 부문 | C3: 작품 이름 | D3: 심사위원 1 | H3: 심사위원 2 | L3: 심사위원 3 | P3: 심사 점수 평균(50) | Q3: 독창성 평균(동점 기준)
D4: 교과 연계성 (15) | E4: 아이디어 독창성 (20) | F4: 표현력 (그림·설명) (15) | G4: 합계 (50) | H4: 교과 연계성 (15) | I4: 아이디어 독창성 (20) | J4: 표현력 (그림·설명) (15) | K4: 합계 (50) | L4: 교과 연계성 (15) | M4: 아이디어 독창성 (20) | N4: 표현력 (그림·설명) (15) | O4: 합계 (50)
A5: S-01 | B5: =IF(A5="","",IFERROR(INDEX(작품목록!$B$4:$B$103,MATCH(A5,작품목록!$A$4:$A$103,0)),"번호 확인")) -> 상상 | C5: =IF(A5="","",IFERROR(INDEX(작품목록!$G$4:$G$103,MATCH(A5,작품목록!$A$4:$A$103,0)),"작품목록에 없음")) -> 받침 친구 로봇 '받침이' | D5: 14 | E5: 18 | F5: 14 | G5: =IF(COUNT(D5:F5)=0,"",SUM(D5:F5)) -> 46 | H5: 13 | I5: 18 | J5: 13 | K5: =IF(COUNT(H5:J5)=0,"",SUM(H5:J5)) -> 44 | L5: 13 | M5: 18 | N5: 14 | O5: =IF(COUNT(L5:N5)=0,"",SUM(L5:N5)) -> 45 | P5: =IF(COUNT(G5,K5,O5)=0,"",ROUND(AVERAGE(G5,K5,O5),2)) -> 45 | Q5: =IF(COUNT(E5,I5,M5)=0,"",ROUND(AVERAGE(E5,I5,M5),2)) -> 18
A6: S-02 | B6: =IF(A6="","",IFERROR(INDEX(작품목록!$B$4:$B$103,MATCH(A6,작품목록!$A$4:$A$103,0)),"번호 확인")) -> 상상 | C6: =IF(A6="","",IFERROR(INDEX(작품목록!$G$4:$G$103,MATCH(A6,작품목록!$A$4:$A$103,0)),"작품목록에 없음")) -> 덧셈 요정 '더하리' | D6: 12 | E6: 16 | F6: 12 | G6: =IF(COUNT(D6:F6)=0,"",SUM(D6:F6)) -> 40 | H6: 12 | I6: 15 | J6: 13 | K6: =IF(COUNT(H6:J6)=0,"",SUM(H6:J6)) -> 40 | L6: 13 | M6: 17 | N6: 13 | O6: =IF(COUNT(L6:N6)=0,"",SUM(L6:N6)) -> 43 | P6: =IF(COUNT(G6,K6,O6)=0,"",ROUND(AVERAGE(G6,K6,O6),2)) -> 41 | Q6: =IF(COUNT(E6,I6,M6)=0,"",ROUND(AVERAGE(E6,I6,M6),2)) -> 16
A7: S-03 | B7: =IF(A7="","",IFERROR(INDEX(작품목록!$B$4:$B$103,MATCH(A7,작품목록!$A$4:$A$103,0)),"번호 확인")) -> 상상 | C7: =IF(A7="","",IFERROR(INDEX(작품목록!$G$4:$G$103,MATCH(A7,작품목록!$A$4:$A$103,0)),"작품목록에 없음")) -> 낙엽 이름 알려 주는 다람쥐 AI | D7: 10 | E7: 15 | F7: 11 | G7: =IF(COUNT(D7:F7)=0,"",SUM(D7:F7)) -> 36 | H7: 11 | I7: 14 | J7: 11 | K7: =IF(COUNT(H7:J7)=0,"",SUM(H7:J7)) -> 36 | L7: 11 | M7: 15 | N7: 12 | O7: =IF(COUNT(L7:N7)=0,"",SUM(L7:N7)) -> 38 | P7: =IF(COUNT(G7,K7,O7)=0,"",ROUND(AVERAGE(G7,K7,O7),2)) -> 36.67 | Q7: =IF(COUNT(E7,I7,M7)=0,"",ROUND(AVERAGE(E7,I7,M7),2)) -> 14.67
A8: S-04 | B8: =IF(A8="","",IFERROR(INDEX(작품목록!$B$4:$B$103,MATCH(A8,작품목록!$A$4:$A$103,0)),"번호 확인")) -> 상상 | C8: =IF(A8="","",IFERROR(INDEX(작품목록!$G$4:$G$103,MATCH(A8,작품목록!$A$4:$A$103,0)),"작품목록에 없음")) -> 자음 모음 블록 친구 | D8: 10 | E8: 12 | F8: 10 | G8: =IF(COUNT(D8:F8)=0,"",SUM(D8:F8)) -> 32 | H8: 10 | I8: 13 | J8: 9 | K8: =IF(COUNT(H8:J8)=0,"",SUM(H8:J8)) -> 32 | L8: 10 | M8: 13 | N8: 10 | O8: =IF(COUNT(L8:N8)=0,"",SUM(L8:N8)) -> 33 | P8: =IF(COUNT(G8,K8,O8)=0,"",ROUND(AVERAGE(G8,K8,O8),2)) -> 32.33 | Q8: =IF(COUNT(E8,I8,M8)=0,"",ROUND(AVERAGE(E8,I8,M8),2)) -> 12.67
A9: S-05 | B9: =IF(A9="","",IFERROR(INDEX(작품목록!$B$4:$B$103,MATCH(A9,작품목록!$A$4:$A$103,0)),"번호 확인")) -> 상상 | C9: =IF(A9="","",IFERROR(INDEX(작품목록!$G$4:$G$103,MATCH(A9,작품목록!$A$4:$A$103,0)),"작품목록에 없음")) -> 시계 읽어 주는 부엉이 | D9: 12 | E9: 17 | F9: 12 | G9: =IF(COUNT(D9:F9)=0,"",SUM(D9:F9)) -> 41 | H9: 13 | I9: 16 | J9: 12 | K9: =IF(COUNT(H9:J9)=0,"",SUM(H9:J9)) -> 41 | L9: 14 | M9: 16 | N9: 13 | O9: =IF(COUNT(L9:N9)=0,"",SUM(L9:N9)) -> 43 | P9: =IF(COUNT(G9,K9,O9)=0,"",ROUND(AVERAGE(G9,K9,O9),2)) -> 41.67 | Q9: =IF(COUNT(E9,I9,M9)=0,"",ROUND(AVERAGE(E9,I9,M9),2)) -> 16.33
A10: S-06 | B10: =IF(A10="","",IFERROR(INDEX(작품목록!$B$4:$B$103,MATCH(A10,작품목록!$A$4:$A$103,0)),"번호 확인")) -> 상상 | C10: =IF(A10="","",IFERROR(INDEX(작품목록!$G$4:$G$103,MATCH(A10,작품목록!$A$4:$A$103,0)),"작품목록에 없음")) -> 학교 길 안내 로봇 '길동이' | D10: 10 | E10: 13 | F10: 9 | G10: =IF(COUNT(D10:F10)=0,"",SUM(D10:F10)) -> 32 | H10: 10 | I10: 12 | J10: 9 | K10: =IF(COUNT(H10:J10)=0,"",SUM(H10:J10)) -> 31 | L10: 10 | M10: 12 | N10: 9 | O10: =IF(COUNT(L10:N10)=0,"",SUM(L10:N10)) -> 31 | P10: =IF(COUNT(G10,K10,O10)=0,"",ROUND(AVERAGE(G10,K10,O10),2)) -> 31.33 | Q10: =IF(COUNT(E10,I10,M10)=0,"",ROUND(AVERAGE(E10,I10,M10),2)) -> 12.33
A11: S-07 | B11: =IF(A11="","",IFERROR(INDEX(작품목록!$B$4:$B$103,MATCH(A11,작품목록!$A$4:$A$103,0)),"번호 확인")) -> 상상 | C11: =IF(A11="","",IFERROR(INDEX(작품목록!$G$4:$G$103,MATCH(A11,작품목록!$A$4:$A$103,0)),"작품목록에 없음")) -> 구구단 노래 상자 | D11: 11 | E11: 14 | F11: 11 | G11: =IF(COUNT(D11:F11)=0,"",SUM(D11:F11)) -> 36 | H11: 12 | I11: 16 | J11: 11 | K11: =IF(COUNT(H11:J11)=0,"",SUM(H11:J11)) -> 39 | L11: 10 | M11: 14 | N11: 10 | O11: =IF(COUNT(L11:N11)=0,"",SUM(L11:N11)) -> 34 | P11: =IF(COUNT(G11,K11,O11)=0,"",ROUND(AVERAGE(G11,K11,O11),2)) -> 36.33 | Q11: =IF(COUNT(E11,I11,M11)=0,"",ROUND(AVERAGE(E11,I11,M11),2)) -> 14.67
A12: S-08 | B12: =IF(A12="","",IFERROR(INDEX(작품목록!$B$4:$B$103,MATCH(A12,작품목록!$A$4:$A$103,0)),"번호 확인")) -> 상상 | C12: =IF(A12="","",IFERROR(INDEX(작품목록!$G$4:$G$103,MATCH(A12,작품목록!$A$4:$A$103,0)),"작품목록에 없음")) -> 또박또박 읽기 마이크 | D12: 10 | E12: 15 | F12: 11 | G12: =IF(COUNT(D12:F12)=0,"",SUM(D12:F12)) -> 36 | H12: 12 | I12: 14 | J12: 11 | K12: =IF(COUNT(H12:J12)=0,"",SUM(H12:J12)) -> 37 | L12: 11 | M12: 15 | N12: 11 | O12: =IF(COUNT(L12:N12)=0,"",SUM(L12:N12)) -> 37 | P12: =IF(COUNT(G12,K12,O12)=0,"",ROUND(AVERAGE(G12,K12,O12),2)) -> 36.67 | Q12: =IF(COUNT(E12,I12,M12)=0,"",ROUND(AVERAGE(E12,I12,M12),2)) -> 14.67
B13: =IF(A13="","",IFERROR(INDEX(작품목록!$B$4:$B$103,MATCH(A13,작품목록!$A$4:$A$103,0)),"번호 확인")) | C13: =IF(A13="","",IFERROR(INDEX(작품목록!$G$4:$G$103,MATCH(A13,작품목록!$A$4:$A$103,0)),"작품목록에 없음")) | G13: =IF(COUNT(D13:F13)=0,"",SUM(D13:F13)) | K13: =IF(COUNT(H13:J13)=0,"",SUM(H13:J13)) | O13: =IF(COUNT(L13:N13)=0,"",SUM(L13:N13)) | P13: =IF(COUNT(G13,K13,O13)=0,"",ROUND(AVERAGE(G13,K13,O13),2)) | Q13: =IF(COUNT(E13,I13,M13)=0,"",ROUND(AVERAGE(E13,I13,M13),2))
B14: =IF(A14="","",IFERROR(INDEX(작품목록!$B$4:$B$103,MATCH(A14,작품목록!$A$4:$A$103,0)),"번호 확인")) | C14: =IF(A14="","",IFERROR(INDEX(작품목록!$G$4:$G$103,MATCH(A14,작품목록!$A$4:$A$103,0)),"작품목록에 없음")) | G14: =IF(COUNT(D14:F14)=0,"",SUM(D14:F14)) | K14: =IF(COUNT(H14:J14)=0,"",SUM(H14:J14)) | O14: =IF(COUNT(L14:N14)=0,"",SUM(L14:N14)) | P14: =IF(COUNT(G14,K14,O14)=0,"",ROUND(AVERAGE(G14,K14,O14),2)) | Q14: =IF(COUNT(E14,I14,M14)=0,"",ROUND(AVERAGE(E14,I14,M14),2))
B15: =IF(A15="","",IFERROR(INDEX(작품목록!$B$4:$B$103,MATCH(A15,작품목록!$A$4:$A$103,0)),"번호 확인")) | C15: =IF(A15="","",IFERROR(INDEX(작품목록!$G$4:$G$103,MATCH(A15,작품목록!$A$4:$A$103,0)),"작품목록에 없음")) | G15: =IF(COUNT(D15:F15)=0,"",SUM(D15:F15)) | K15: =IF(COUNT(H15:J15)=0,"",SUM(H15:J15)) | O15: =IF(COUNT(L15:N15)=0,"",SUM(L15:N15)) | P15: =IF(COUNT(G15,K15,O15)=0,"",ROUND(AVERAGE(G15,K15,O15),2)) | Q15: =IF(COUNT(E15,I15,M15)=0,"",ROUND(AVERAGE(E15,I15,M15),2))
B16: =IF(A16="","",IFERROR(INDEX(작품목록!$B$4:$B$103,MATCH(A16,작품목록!$A$4:$A$103,0)),"번호 확인")) | C16: =IF(A16="","",IFERROR(INDEX(작품목록!$G$4:$G$103,MATCH(A16,작품목록!$A$4:$A$103,0)),"작품목록에 없음")) | G16: =IF(COUNT(D16:F16)=0,"",SUM(D16:F16)) | K16: =IF(COUNT(H16:J16)=0,"",SUM(H16:J16)) | O16: =IF(COUNT(L16:N16)=0,"",SUM(L16:N16)) | P16: =IF(COUNT(G16,K16,O16)=0,"",ROUND(AVERAGE(G16,K16,O16),2)) | Q16: =IF(COUNT(E16,I16,M16)=0,"",ROUND(AVERAGE(E16,I16,M16),2))
B17: =IF(A17="","",IFERROR(INDEX(작품목록!$B$4:$B$103,MATCH(A17,작품목록!$A$4:$A$103,0)),"번호 확인")) | C17: =IF(A17="","",IFERROR(INDEX(작품목록!$G$4:$G$103,MATCH(A17,작품목록!$A$4:$A$103,0)),"작품목록에 없음")) | G17: =IF(COUNT(D17:F17)=0,"",SUM(D17:F17)) | K17: =IF(COUNT(H17:J17)=0,"",SUM(H17:J17)) | O17: =IF(COUNT(L17:N17)=0,"",SUM(L17:N17)) | P17: =IF(COUNT(G17,K17,O17)=0,"",ROUND(AVERAGE(G17,K17,O17),2)) | Q17: =IF(COUNT(E17,I17,M17)=0,"",ROUND(AVERAGE(E17,I17,M17),2))
B18: =IF(A18="","",IFERROR(INDEX(작품목록!$B$4:$B$103,MATCH(A18,작품목록!$A$4:$A$103,0)),"번호 확인")) | C18: =IF(A18="","",IFERROR(INDEX(작품목록!$G$4:$G$103,MATCH(A18,작품목록!$A$4:$A$103,0)),"작품목록에 없음")) | G18: =IF(COUNT(D18:F18)=0,"",SUM(D18:F18)) | K18: =IF(COUNT(H18:J18)=0,"",SUM(H18:J18)) | O18: =IF(COUNT(L18:N18)=0,"",SUM(L18:N18)) | P18: =IF(COUNT(G18,K18,O18)=0,"",ROUND(AVERAGE(G18,K18,O18),2)) | Q18: =IF(COUNT(E18,I18,M18)=0,"",ROUND(AVERAGE(E18,I18,M18),2))
B19: =IF(A19="","",IFERROR(INDEX(작품목록!$B$4:$B$103,MATCH(A19,작품목록!$A$4:$A$103,0)),"번호 확인")) | C19: =IF(A19="","",IFERROR(INDEX(작품목록!$G$4:$G$103,MATCH(A19,작품목록!$A$4:$A$103,0)),"작품목록에 없음")) | G19: =IF(COUNT(D19:F19)=0,"",SUM(D19:F19)) | K19: =IF(COUNT(H19:J19)=0,"",SUM(H19:J19)) | O19: =IF(COUNT(L19:N19)=0,"",SUM(L19:N19)) | P19: =IF(COUNT(G19,K19,O19)=0,"",ROUND(AVERAGE(G19,K19,O19),2)) | Q19: =IF(COUNT(E19,I19,M19)=0,"",ROUND(AVERAGE(E19,I19,M19),2))
B20: =IF(A20="","",IFERROR(INDEX(작품목록!$B$4:$B$103,MATCH(A20,작품목록!$A$4:$A$103,0)),"번호 확인")) | C20: =IF(A20="","",IFERROR(INDEX(작품목록!$G$4:$G$103,MATCH(A20,작품목록!$A$4:$A$103,0)),"작품목록에 없음")) | G20: =IF(COUNT(D20:F20)=0,"",SUM(D20:F20)) | K20: =IF(COUNT(H20:J20)=0,"",SUM(H20:J20)) | O20: =IF(COUNT(L20:N20)=0,"",SUM(L20:N20)) | P20: =IF(COUNT(G20,K20,O20)=0,"",ROUND(AVERAGE(G20,K20,O20),2)) | Q20: =IF(COUNT(E20,I20,M20)=0,"",ROUND(AVERAGE(E20,I20,M20),2))
B21: =IF(A21="","",IFERROR(INDEX(작품목록!$B$4:$B$103,MATCH(A21,작품목록!$A$4:$A$103,0)),"번호 확인")) | C21: =IF(A21="","",IFERROR(INDEX(작품목록!$G$4:$G$103,MATCH(A21,작품목록!$A$4:$A$103,0)),"작품목록에 없음")) | G21: =IF(COUNT(D21:F21)=0,"",SUM(D21:F21)) | K21: =IF(COUNT(H21:J21)=0,"",SUM(H21:J21)) | O21: =IF(COUNT(L21:N21)=0,"",SUM(L21:N21)) | P21: =IF(COUNT(G21,K21,O21)=0,"",ROUND(AVERAGE(G21,K21,O21),2)) | Q21: =IF(COUNT(E21,I21,M21)=0,"",ROUND(AVERAGE(E21,I21,M21),2))
B22: =IF(A22="","",IFERROR(INDEX(작품목록!$B$4:$B$103,MATCH(A22,작품목록!$A$4:$A$103,0)),"번호 확인")) | C22: =IF(A22="","",IFERROR(INDEX(작품목록!$G$4:$G$103,MATCH(A22,작품목록!$A$4:$A$103,0)),"작품목록에 없음")) | G22: =IF(COUNT(D22:F22)=0,"",SUM(D22:F22)) | K22: =IF(COUNT(H22:J22)=0,"",SUM(H22:J22)) | O22: =IF(COUNT(L22:N22)=0,"",SUM(L22:N22)) | P22: =IF(COUNT(G22,K22,O22)=0,"",ROUND(AVERAGE(G22,K22,O22),2)) | Q22: =IF(COUNT(E22,I22,M22)=0,"",ROUND(AVERAGE(E22,I22,M22),2))
B23: =IF(A23="","",IFERROR(INDEX(작품목록!$B$4:$B$103,MATCH(A23,작품목록!$A$4:$A$103,0)),"번호 확인")) | C23: =IF(A23="","",IFERROR(INDEX(작품목록!$G$4:$G$103,MATCH(A23,작품목록!$A$4:$A$103,0)),"작품목록에 없음")) | G23: =IF(COUNT(D23:F23)=0,"",SUM(D23:F23)) | K23: =IF(COUNT(H23:J23)=0,"",SUM(H23:J23)) | O23: =IF(COUNT(L23:N23)=0,"",SUM(L23:N23)) | P23: =IF(COUNT(G23,K23,O23)=0,"",ROUND(AVERAGE(G23,K23,O23),2)) | Q23: =IF(COUNT(E23,I23,M23)=0,"",ROUND(AVERAGE(E23,I23,M23),2))
B24: =IF(A24="","",IFERROR(INDEX(작품목록!$B$4:$B$103,MATCH(A24,작품목록!$A$4:$A$103,0)),"번호 확인")) | C24: =IF(A24="","",IFERROR(INDEX(작품목록!$G$4:$G$103,MATCH(A24,작품목록!$A$4:$A$103,0)),"작품목록에 없음")) | G24: =IF(COUNT(D24:F24)=0,"",SUM(D24:F24)) | K24: =IF(COUNT(H24:J24)=0,"",SUM(H24:J24)) | O24: =IF(COUNT(L24:N24)=0,"",SUM(L24:N24)) | P24: =IF(COUNT(G24,K24,O24)=0,"",ROUND(AVERAGE(G24,K24,O24),2)) | Q24: =IF(COUNT(E24,I24,M24)=0,"",ROUND(AVERAGE(E24,I24,M24),2))
... B104: =IF(A104="","",IFERROR(INDEX(작품목록!$B$4:$B$103,MATCH(A104,작품목록!$A$4:$A$103,0)),"번호 확인")) | C104: =IF(A104="","",IFERROR(INDEX(작품목록!$G$4:$G$103,MATCH(A104,작품목록!$A$4:$A$103,0)),"작품목록에 없음")) | G104: =IF(COUNT(D104:F104)=0,"",SUM(D104:F104)) | K104: =IF(COUNT(H104:J104)=0,"",SUM(H104:J104)) | O104: =IF(COUNT(L104:N104)=0,"",SUM(L104:N104)) | P104: =IF(COUNT(G104,K104,O104)=0,"",ROUND(AVERAGE(G104,K104,O104),2)) | Q104: =IF(COUNT(E104,I104,M104)=0,"",ROUND(AVERAGE(E104,I104,M104),2))

Sheet 좋아요 수
A1: 좋아요 수 집계 (블록·바이브: 온라인 작품 갤러리 좋아요 / 상상: 스티커)
A2: 투표가 끝나면(11. 13.(금)) 갤러리 결과에서 '작품번호'와 '좋아요 수' 두 열만 복사해 A6에 값만 붙여 넣으세요(제목 줄 빼고, 순서 상관없음). 상상 부문 스티커 수는 I열에 입력해요.
A3: ① 갤러리 결과 붙여넣기 (노란 칸) | E3: ② 작품별 좋아요 수 (자동) — 상상 부문은 I열에 스티커 수 입력
C4: =IF(COUNTA(A6:A105)=0,"","붙여 넣은 작품 "&COUNTA(A6:A105)&"개 · 좋아요 합계 "&SUM(B6:B105)&"개") -> 붙여 넣은 작품 16개 · 좋아요 합계 544개
A5: 작품번호 | B5: 좋아요 수 | C5: 확인 | E5: 작품번호 | F5: 부문 | G5: 작품 이름 | H5: 갤러리 좋아요 | I5: 스티커 수 (상상 입력) | J5: 최종 좋아요 수 | K5: 부문 내 순위
A6: V-01 | B6: 60 | C6: =IF(A6="","",IF(COUNTIF($A$6:$A$105,A6)>1,"번호 중복(한 번만 남기세요)",IF(COUNTIF(작품목록!$A$4:$A$103,A6)=0,"작품목록에 없는 번호",IF(ISNUMBER(B6),"","좋아요 수가 숫자가 아님")))) | E6: =IF(작품목록!A4="","",작품목록!A4) -> B-01 | F6: =IF(E6="","",작품목록!B4&"") -> 블록 | G6: =IF(E6="","",작품목록!G4&"") -> 구구단 우주선 | H6: =IF(E6="","",IF(F6="상상","-",SUMIF($A$6:$A$105,E6,$B$6:$B$105))) -> 58 | J6: =IF(E6="","",IF(F6="상상",N(I6),N(H6))) -> 58 | K6: =IF(E6="","",COUNTIFS($F$6:$F$105,F6,$J$6:$J$105,">"&J6)+1) -> 1
A7: B-01 | B7: 58 | C7: =IF(A7="","",IF(COUNTIF($A$6:$A$105,A7)>1,"번호 중복(한 번만 남기세요)",IF(COUNTIF(작품목록!$A$4:$A$103,A7)=0,"작품목록에 없는 번호",IF(ISNUMBER(B7),"","좋아요 수가 숫자가 아님")))) | E7: =IF(작품목록!A5="","",작품목록!A5) -> B-02 | F7: =IF(E7="","",작품목록!B5&"") -> 블록 | G7: =IF(E7="","",작품목록!G5&"") -> 영어 단어 짝 맞추기 | H7: =IF(E7="","",IF(F7="상상","-",SUMIF($A$6:$A$105,E7,$B$6:$B$105))) -> 41 | J7: =IF(E7="","",IF(F7="상상",N(I7),N(H7))) -> 41 | K7: =IF(E7="","",COUNTIFS($F$6:$F$105,F7,$J$6:$J$105,">"&J7)+1) -> 3
A8: B-04 | B8: 47 | C8: =IF(A8="","",IF(COUNTIF($A$6:$A$105,A8)>1,"번호 중복(한 번만 남기세요)",IF(COUNTIF(작품목록!$A$4:$A$103,A8)=0,"작품목록에 없는 번호",IF(ISNUMBER(B8),"","좋아요 수가 숫자가 아님")))) | E8: =IF(작품목록!A6="","",작품목록!A6) -> B-03 | F8: =IF(E8="","",작품목록!B6&"") -> 블록 | G8: =IF(E8="","",작품목록!G6&"") -> 씨앗 키우기 순서 게임 | H8: =IF(E8="","",IF(F8="상상","-",SUMIF($A$6:$A$105,E8,$B$6:$B$105))) -> 23 | J8: =IF(E8="","",IF(F8="상상",N(I8),N(H8))) -> 23 | K8: =IF(E8="","",COUNTIFS($F$6:$F$105,F8,$J$6:$J$105,">"&J8)+1) -> 6
A9: V-07 | B9: 45 | C9: =IF(A9="","",IF(COUNTIF($A$6:$A$105,A9)>1,"번호 중복(한 번만 남기세요)",IF(COUNTIF(작품목록!$A$4:$A$103,A9)=0,"작품목록에 없는 번호",IF(ISNUMBER(B9),"","좋아요 수가 숫자가 아님")))) | E9: =IF(작품목록!A7="","",작품목록!A7) -> B-04 | F9: =IF(E9="","",작품목록!B7&"") -> 블록 | G9: =IF(E9="","",작품목록!G7&"") -> 배수 사냥꾼 | H9: =IF(E9="","",IF(F9="상상","-",SUMIF($A$6:$A$105,E9,$B$6:$B$105))) -> 47 | J9: =IF(E9="","",IF(F9="상상",N(I9),N(H9))) -> 47 | K9: =IF(E9="","",COUNTIFS($F$6:$F$105,F9,$J$6:$J$105,">"&J9)+1) -> 2
A10: V-02 | B10: 42 | C10: =IF(A10="","",IF(COUNTIF($A$6:$A$105,A10)>1,"번호 중복(한 번만 남기세요)",IF(COUNTIF(작품목록!$A$4:$A$103,A10)=0,"작품목록에 없는 번호",IF(ISNUMBER(B10),"","좋아요 수가 숫자가 아님")))) | E10: =IF(작품목록!A8="","",작품목록!A8) -> B-05 | F10: =IF(E10="","",작품목록!B8&"") -> 블록 | G10: =IF(E10="","",작품목록!G8&"") -> 낱말 바구니 분류하기 | H10: =IF(E10="","",IF(F10="상상","-",SUMIF($A$6:$A$105,E10,$B$6:$B$105))) -> 15 | J10: =IF(E10="","",IF(F10="상상",N(I10),N(H10))) -> 15 | K10: =IF(E10="","",COUNTIFS($F$6:$F$105,F10,$J$6:$J$105,">"&J10)+1) -> 8
A11: B-02 | B11: 41 | C11: =IF(A11="","",IF(COUNTIF($A$6:$A$105,A11)>1,"번호 중복(한 번만 남기세요)",IF(COUNTIF(작품목록!$A$4:$A$103,A11)=0,"작품목록에 없는 번호",IF(ISNUMBER(B11),"","좋아요 수가 숫자가 아님")))) | E11: =IF(작품목록!A9="","",작품목록!A9) -> B-06 | F11: =IF(E11="","",작품목록!B9&"") -> 블록 | G11: =IF(E11="","",작품목록!G9&"") -> 행성 순서 맞히기 | H11: =IF(E11="","",IF(F11="상상","-",SUMIF($A$6:$A$105,E11,$B$6:$B$105))) -> 33 | J11: =IF(E11="","",IF(F11="상상",N(I11),N(H11))) -> 33 | K11: =IF(E11="","",COUNTIFS($F$6:$F$105,F11,$J$6:$J$105,">"&J11)+1) -> 5
A12: V-05 | B12: 37 | C12: =IF(A12="","",IF(COUNTIF($A$6:$A$105,A12)>1,"번호 중복(한 번만 남기세요)",IF(COUNTIF(작품목록!$A$4:$A$103,A12)=0,"작품목록에 없는 번호",IF(ISNUMBER(B12),"","좋아요 수가 숫자가 아님")))) | E12: =IF(작품목록!A10="","",작품목록!A10) -> B-07 | F12: =IF(E12="","",작품목록!B10&"") -> 블록 | G12: =IF(E12="","",작품목록!G10&"") -> 우리 지역 지도 탐험 | H12: =IF(E12="","",IF(F12="상상","-",SUMIF($A$6:$A$105,E12,$B$6:$B$105))) -> 19 | J12: =IF(E12="","",IF(F12="상상",N(I12),N(H12))) -> 19 | K12: =IF(E12="","",COUNTIFS($F$6:$F$105,F12,$J$6:$J$105,">"&J12)+1) -> 7
A13: B-08 | B13: 36 | C13: =IF(A13="","",IF(COUNTIF($A$6:$A$105,A13)>1,"번호 중복(한 번만 남기세요)",IF(COUNTIF(작품목록!$A$4:$A$103,A13)=0,"작품목록에 없는 번호",IF(ISNUMBER(B13),"","좋아요 수가 숫자가 아님")))) | E13: =IF(작품목록!A11="","",작품목록!A11) -> B-08 | F13: =IF(E13="","",작품목록!B11&"") -> 블록 | G13: =IF(E13="","",작품목록!G11&"") -> 분수 피자 가게 | H13: =IF(E13="","",IF(F13="상상","-",SUMIF($A$6:$A$105,E13,$B$6:$B$105))) -> 36 | J13: =IF(E13="","",IF(F13="상상",N(I13),N(H13))) -> 36 | K13: =IF(E13="","",COUNTIFS($F$6:$F$105,F13,$J$6:$J$105,">"&J13)+1) -> 4
A14: B-06 | B14: 33 | C14: =IF(A14="","",IF(COUNTIF($A$6:$A$105,A14)>1,"번호 중복(한 번만 남기세요)",IF(COUNTIF(작품목록!$A$4:$A$103,A14)=0,"작품목록에 없는 번호",IF(ISNUMBER(B14),"","좋아요 수가 숫자가 아님")))) | E14: =IF(작품목록!A12="","",작품목록!A12) -> V-01 | F14: =IF(E14="","",작품목록!B12&"") -> 바이브 | G14: =IF(E14="","",작품목록!G12&"") -> 각도 탐정 게임 | H14: =IF(E14="","",IF(F14="상상","-",SUMIF($A$6:$A$105,E14,$B$6:$B$105))) -> 60 | J14: =IF(E14="","",IF(F14="상상",N(I14),N(H14))) -> 60 | K14: =IF(E14="","",COUNTIFS($F$6:$F$105,F14,$J$6:$J$105,">"&J14)+1) -> 1
A15: V-03 | B15: 31 | C15: =IF(A15="","",IF(COUNTIF($A$6:$A$105,A15)>1,"번호 중복(한 번만 남기세요)",IF(COUNTIF(작품목록!$A$4:$A$103,A15)=0,"작품목록에 없는 번호",IF(ISNUMBER(B15),"","좋아요 수가 숫자가 아님")))) | E15: =IF(작품목록!A13="","",작품목록!A13) -> V-02 | F15: =IF(E15="","",작품목록!B13&"") -> 바이브 | G15: =IF(E15="","",작품목록!G13&"") -> 우리나라 시·도 퀴즈 | H15: =IF(E15="","",IF(F15="상상","-",SUMIF($A$6:$A$105,E15,$B$6:$B$105))) -> 42 | J15: =IF(E15="","",IF(F15="상상",N(I15),N(H15))) -> 42 | K15: =IF(E15="","",COUNTIFS($F$6:$F$105,F15,$J$6:$J$105,">"&J15)+1) -> 3
A16: V-06 | B16: 27 | C16: =IF(A16="","",IF(COUNTIF($A$6:$A$105,A16)>1,"번호 중복(한 번만 남기세요)",IF(COUNTIF(작품목록!$A$4:$A$103,A16)=0,"작품목록에 없는 번호",IF(ISNUMBER(B16),"","좋아요 수가 숫자가 아님")))) | E16: =IF(작품목록!A14="","",작품목록!A14) -> V-03 | F16: =IF(E16="","",작품목록!B14&"") -> 바이브 | G16: =IF(E16="","",작품목록!G14&"") -> 지시약 색깔 실험실 | H16: =IF(E16="","",IF(F16="상상","-",SUMIF($A$6:$A$105,E16,$B$6:$B$105))) -> 31 | J16: =IF(E16="","",IF(F16="상상",N(I16),N(H16))) -> 31 | K16: =IF(E16="","",COUNTIFS($F$6:$F$105,F16,$J$6:$J$105,">"&J16)+1) -> 5
A17: B-03 | B17: 23 | C17: =IF(A17="","",IF(COUNTIF($A$6:$A$105,A17)>1,"번호 중복(한 번만 남기세요)",IF(COUNTIF(작품목록!$A$4:$A$103,A17)=0,"작품목록에 없는 번호",IF(ISNUMBER(B17),"","좋아요 수가 숫자가 아님")))) | E17: =IF(작품목록!A15="","",작품목록!A15) -> V-04 | F17: =IF(E17="","",작품목록!B15&"") -> 바이브 | G17: =IF(E17="","",작품목록!G15&"") -> 중심 문장 찾기 놀이 | H17: =IF(E17="","",IF(F17="상상","-",SUMIF($A$6:$A$105,E17,$B$6:$B$105))) -> 18 | J17: =IF(E17="","",IF(F17="상상",N(I17),N(H17))) -> 18 | K17: =IF(E17="","",COUNTIFS($F$6:$F$105,F17,$J$6:$J$105,">"&J17)+1) -> 7
... A21: V-08 | B21: 12 | C21: =IF(A21="","",IF(COUNTIF($A$6:$A$105,A21)>1,"번호 중복(한 번만 남기세요)",IF(COUNTIF(작품목록!$A$4:$A$103,A21)=0,"작품목록에 없는 번호",IF(ISNUMBER(B21),"","좋아요 수가 숫자가 아님")))) | E21: =IF(작품목록!A19="","",작품목록!A19) -> V-08 | F21: =IF(E21="","",작품목록!B19&"") -> 바이브 | G21: =IF(E21="","",작품목록!G19&"") -> 고장 지도 기호 카드 | H21: =IF(E21="","",IF(F21="상상","-",SUMIF($A$6:$A$105,E21,$B$6:$B$105))) -> 12 | J21: =IF(E21="","",IF(F21="상상",N(I21),N(H21))) -> 12 | K21: =IF(E21="","",COUNTIFS($F$6:$F$105,F21,$J$6:$J$105,">"&J21)+1) -> 8
C22: =IF(A22="","",IF(COUNTIF($A$6:$A$105,A22)>1,"번호 중복(한 번만 남기세요)",IF(COUNTIF(작품목록!$A$4:$A$103,A22)=0,"작품목록에 없는 번호",IF(ISNUMBER(B22),"","좋아요 수가 숫자가 아님")))) | E22: =IF(작품목록!A20="","",작품목록!A20) -> S-01 | F22: =IF(E22="","",작품목록!B20&"") -> 상상 | G22: =IF(E22="","",작품목록!G20&"") -> 받침 친구 로봇 '받침이' | H22: =IF(E22="","",IF(F22="상상","-",SUMIF($A$6:$A$105,E22,$B$6:$B$105))) -> - | I22: 38 | J22: =IF(E22="","",IF(F22="상상",N(I22),N(H22))) -> 38 | K22: =IF(E22="","",COUNTIFS($F$6:$F$105,F22,$J$6:$J$105,">"&J22)+1) -> 1
C23: =IF(A23="","",IF(COUNTIF($A$6:$A$105,A23)>1,"번호 중복(한 번만 남기세요)",IF(COUNTIF(작품목록!$A$4:$A$103,A23)=0,"작품목록에 없는 번호",IF(ISNUMBER(B23),"","좋아요 수가 숫자가 아님")))) | E23: =IF(작품목록!A21="","",작품목록!A21) -> S-02 | F23: =IF(E23="","",작품목록!B21&"") -> 상상 | G23: =IF(E23="","",작품목록!G21&"") -> 덧셈 요정 '더하리' | H23: =IF(E23="","",IF(F23="상상","-",SUMIF($A$6:$A$105,E23,$B$6:$B$105))) -> - | I23: 27 | J23: =IF(E23="","",IF(F23="상상",N(I23),N(H23))) -> 27 | K23: =IF(E23="","",COUNTIFS($F$6:$F$105,F23,$J$6:$J$105,">"&J23)+1) -> 3
C24: =IF(A24="","",IF(COUNTIF($A$6:$A$105,A24)>1,"번호 중복(한 번만 남기세요)",IF(COUNTIF(작품목록!$A$4:$A$103,A24)=0,"작품목록에 없는 번호",IF(ISNUMBER(B24),"","좋아요 수가 숫자가 아님")))) | E24: =IF(작품목록!A22="","",작품목록!A22) -> S-03 | F24: =IF(E24="","",작품목록!B22&"") -> 상상 | G24: =IF(E24="","",작품목록!G22&"") -> 낙엽 이름 알려 주는 다람쥐 AI | H24: =IF(E24="","",IF(F24="상상","-",SUMIF($A$6:$A$105,E24,$B$6:$B$105))) -> - | I24: 19 | J24: =IF(E24="","",IF(F24="상상",N(I24),N(H24))) -> 19 | K24: =IF(E24="","",COUNTIFS($F$6:$F$105,F24,$J$6:$J$105,">"&J24)+1) -> 6
C25: =IF(A25="","",IF(COUNTIF($A$6:$A$105,A25)>1,"번호 중복(한 번만 남기세요)",IF(COUNTIF(작품목록!$A$4:$A$103,A25)=0,"작품목록에 없는 번호",IF(ISNUMBER(B25),"","좋아요 수가 숫자가 아님")))) | E25: =IF(작품목록!A23="","",작품목록!A23) -> S-04 | F25: =IF(E25="","",작품목록!B23&"") -> 상상 | G25: =IF(E25="","",작품목록!G23&"") -> 자음 모음 블록 친구 | H25: =IF(E25="","",IF(F25="상상","-",SUMIF($A$6:$A$105,E25,$B$6:$B$105))) -> - | I25: 22 | J25: =IF(E25="","",IF(F25="상상",N(I25),N(H25))) -> 22 | K25: =IF(E25="","",COUNTIFS($F$6:$F$105,F25,$J$6:$J$105,">"&J25)+1) -> 5
C26: =IF(A26="","",IF(COUNTIF($A$6:$A$105,A26)>1,"번호 중복(한 번만 남기세요)",IF(COUNTIF(작품목록!$A$4:$A$103,A26)=0,"작품목록에 없는 번호",IF(ISNUMBER(B26),"","좋아요 수가 숫자가 아님")))) | E26: =IF(작품목록!A24="","",작품목록!A24) -> S-05 | F26: =IF(E26="","",작품목록!B24&"") -> 상상 | G26: =IF(E26="","",작품목록!G24&"") -> 시계 읽어 주는 부엉이 | H26: =IF(E26="","",IF(F26="상상","-",SUMIF($A$6:$A$105,E26,$B$6:$B$105))) -> - | I26: 31 | J26: =IF(E26="","",IF(F26="상상",N(I26),N(H26))) -> 31 | K26: =IF(E26="","",COUNTIFS($F$6:$F$105,F26,$J$6:$J$105,">"&J26)+1) -> 2
C27: =IF(A27="","",IF(COUNTIF($A$6:$A$105,A27)>1,"번호 중복(한 번만 남기세요)",IF(COUNTIF(작품목록!$A$4:$A$103,A27)=0,"작품목록에 없는 번호",IF(ISNUMBER(B27),"","좋아요 수가 숫자가 아님")))) | E27: =IF(작품목록!A25="","",작품목록!A25) -> S-06 | F27: =IF(E27="","",작품목록!B25&"") -> 상상 | G27: =IF(E27="","",작품목록!G25&"") -> 학교 길 안내 로봇 '길동이' | H27: =IF(E27="","",IF(F27="상상","-",SUMIF($A$6:$A$105,E27,$B$6:$B$105))) -> - | I27: 15 | J27: =IF(E27="","",IF(F27="상상",N(I27),N(H27))) -> 15 | K27: =IF(E27="","",COUNTIFS($F$6:$F$105,F27,$J$6:$J$105,">"&J27)+1) -> 7
C28: =IF(A28="","",IF(COUNTIF($A$6:$A$105,A28)>1,"번호 중복(한 번만 남기세요)",IF(COUNTIF(작품목록!$A$4:$A$103,A28)=0,"작품목록에 없는 번호",IF(ISNUMBER(B28),"","좋아요 수가 숫자가 아님")))) | E28: =IF(작품목록!A26="","",작품목록!A26) -> S-07 | F28: =IF(E28="","",작품목록!B26&"") -> 상상 | G28: =IF(E28="","",작품목록!G26&"") -> 구구단 노래 상자 | H28: =IF(E28="","",IF(F28="상상","-",SUMIF($A$6:$A$105,E28,$B$6:$B$105))) -> - | I28: 24 | J28: =IF(E28="","",IF(F28="상상",N(I28),N(H28))) -> 24 | K28: =IF(E28="","",COUNTIFS($F$6:$F$105,F28,$J$6:$J$105,">"&J28)+1) -> 4
C29: =IF(A29="","",IF(COUNTIF($A$6:$A$105,A29)>1,"번호 중복(한 번만 남기세요)",IF(COUNTIF(작품목록!$A$4:$A$103,A29)=0,"작품목록에 없는 번호",IF(ISNUMBER(B29),"","좋아요 수가 숫자가 아님")))) | E29: =IF(작품목록!A27="","",작품목록!A27) -> S-08 | F29: =IF(E29="","",작품목록!B27&"") -> 상상 | G29: =IF(E29="","",작품목록!G27&"") -> 또박또박 읽기 마이크 | H29: =IF(E29="","",IF(F29="상상","-",SUMIF($A$6:$A$105,E29,$B$6:$B$105))) -> - | I29: 12 | J29: =IF(E29="","",IF(F29="상상",N(I29),N(H29))) -> 12 | K29: =IF(E29="","",COUNTIFS($F$6:$F$105,F29,$J$6:$J$105,">"&J29)+1) -> 8
C30: =IF(A30="","",IF(COUNTIF($A$6:$A$105,A30)>1,"번호 중복(한 번만 남기세요)",IF(COUNTIF(작품목록!$A$4:$A$103,A30)=0,"작품목록에 없는 번호",IF(ISNUMBER(B30),"","좋아요 수가 숫자가 아님")))) | E30: =IF(작품목록!A28="","",작품목록!A28) | F30: =IF(E30="","",작품목록!B28&"") | G30: =IF(E30="","",작품목록!G28&"") | H30: =IF(E30="","",IF(F30="상상","-",SUMIF($A$6:$A$105,E30,$B$6:$B$105))) | J30: =IF(E30="","",IF(F30="상상",N(I30),N(H30))) | K30: =IF(E30="","",COUNTIFS($F$6:$F$105,F30,$J$6:$J$105,">"&J30)+1)
C31: =IF(A31="","",IF(COUNTIF($A$6:$A$105,A31)>1,"번호 중복(한 번만 남기세요)",IF(COUNTIF(작품목록!$A$4:$A$103,A31)=0,"작품목록에 없는 번호",IF(ISNUMBER(B31),"","좋아요 수가 숫자가 아님")))) | E31: =IF(작품목록!A29="","",작품목록!A29) | F31: =IF(E31="","",작품목록!B29&"") | G31: =IF(E31="","",작품목록!G29&"") | H31: =IF(E31="","",IF(F31="상상","-",SUMIF($A$6:$A$105,E31,$B$6:$B$105))) | J31: =IF(E31="","",IF(F31="상상",N(I31),N(H31))) | K31: =IF(E31="","",COUNTIFS($F$6:$F$105,F31,$J$6:$J$105,">"&J31)+1)
C32: =IF(A32="","",IF(COUNTIF($A$6:$A$105,A32)>1,"번호 중복(한 번만 남기세요)",IF(COUNTIF(작품목록!$A$4:$A$103,A32)=0,"작품목록에 없는 번호",IF(ISNUMBER(B32),"","좋아요 수가 숫자가 아님")))) | E32: =IF(작품목록!A30="","",작품목록!A30) | F32: =IF(E32="","",작품목록!B30&"") | G32: =IF(E32="","",작품목록!G30&"") | H32: =IF(E32="","",IF(F32="상상","-",SUMIF($A$6:$A$105,E32,$B$6:$B$105))) | J32: =IF(E32="","",IF(F32="상상",N(I32),N(H32))) | K32: =IF(E32="","",COUNTIFS($F$6:$F$105,F32,$J$6:$J$105,">"&J32)+1)
C33: =IF(A33="","",IF(COUNTIF($A$6:$A$105,A33)>1,"번호 중복(한 번만 남기세요)",IF(COUNTIF(작품목록!$A$4:$A$103,A33)=0,"작품목록에 없는 번호",IF(ISNUMBER(B33),"","좋아요 수가 숫자가 아님")))) | E33: =IF(작품목록!A31="","",작품목록!A31) | F33: =IF(E33="","",작품목록!B31&"") | G33: =IF(E33="","",작품목록!G31&"") | H33: =IF(E33="","",IF(F33="상상","-",SUMIF($A$6:$A$105,E33,$B$6:$B$105))) | J33: =IF(E33="","",IF(F33="상상",N(I33),N(H33))) | K33: =IF(E33="","",COUNTIFS($F$6:$F$105,F33,$J$6:$J$105,">"&J33)+1)
C34: =IF(A34="","",IF(COUNTIF($A$6:$A$105,A34)>1,"번호 중복(한 번만 남기세요)",IF(COUNTIF(작품목록!$A$4:$A$103,A34)=0,"작품목록에 없는 번호",IF(ISNUMBER(B34),"","좋아요 수가 숫자가 아님")))) | E34: =IF(작품목록!A32="","",작품목록!A32) | F34: =IF(E34="","",작품목록!B32&"") | G34: =IF(E34="","",작품목록!G32&"") | H34: =IF(E34="","",IF(F34="상상","-",SUMIF($A$6:$A$105,E34,$B$6:$B$105))) | J34: =IF(E34="","",IF(F34="상상",N(I34),N(H34))) | K34: =IF(E34="","",COUNTIFS($F$6:$F$105,F34,$J$6:$J$105,">"&J34)+1)
C35: =IF(A35="","",IF(COUNTIF($A$6:$A$105,A35)>1,"번호 중복(한 번만 남기세요)",IF(COUNTIF(작품목록!$A$4:$A$103,A35)=0,"작품목록에 없는 번호",IF(ISNUMBER(B35),"","좋아요 수가 숫자가 아님")))) | E35: =IF(작품목록!A33="","",작품목록!A33) | F35: =IF(E35="","",작품목록!B33&"") | G35: =IF(E35="","",작품목록!G33&"") | H35: =IF(E35="","",IF(F35="상상","-",SUMIF($A$6:$A$105,E35,$B$6:$B$105))) | J35: =IF(E35="","",IF(F35="상상",N(I35),N(H35))) | K35: =IF(E35="","",COUNTIFS($F$6:$F$105,F35,$J$6:$J$105,">"&J35)+1)
C36: =IF(A36="","",IF(COUNTIF($A$6:$A$105,A36)>1,"번호 중복(한 번만 남기세요)",IF(COUNTIF(작품목록!$A$4:$A$103,A36)=0,"작품목록에 없는 번호",IF(ISNUMBER(B36),"","좋아요 수가 숫자가 아님")))) | E36: =IF(작품목록!A34="","",작품목록!A34) | F36: =IF(E36="","",작품목록!B34&"") | G36: =IF(E36="","",작품목록!G34&"") | H36: =IF(E36="","",IF(F36="상상","-",SUMIF($A$6:$A$105,E36,$B$6:$B$105))) | J36: =IF(E36="","",IF(F36="상상",N(I36),N(H36))) | K36: =IF(E36="","",COUNTIFS($F$6:$F$105,F36,$J$6:$J$105,">"&J36)+1)
C37: =IF(A37="","",IF(COUNTIF($A$6:$A$105,A37)>1,"번호 중복(한 번만 남기세요)",IF(COUNTIF(작품목록!$A$4:$A$103,A37)=0,"작품목록에 없는 번호",IF(ISNUMBER(B37),"","좋아요 수가 숫자가 아님")))) | E37: =IF(작품목록!A35="","",작품목록!A35) | F37: =IF(E37="","",작품목록!B35&"") | G37: =IF(E37="","",작품목록!G35&"") | H37: =IF(E37="","",IF(F37="상상","-",SUMIF($A$6:$A$105,E37,$B$6:$B$105))) | J37: =IF(E37="","",IF(F37="상상",N(I37),N(H37))) | K37: =IF(E37="","",COUNTIFS($F$6:$F$105,F37,$J$6:$J$105,">"&J37)+1)
C38: =IF(A38="","",IF(COUNTIF($A$6:$A$105,A38)>1,"번호 중복(한 번만 남기세요)",IF(COUNTIF(작품목록!$A$4:$A$103,A38)=0,"작품목록에 없는 번호",IF(ISNUMBER(B38),"","좋아요 수가 숫자가 아님")))) | E38: =IF(작품목록!A36="","",작품목록!A36) | F38: =IF(E38="","",작품목록!B36&"") | G38: =IF(E38="","",작품목록!G36&"") | H38: =IF(E38="","",IF(F38="상상","-",SUMIF($A$6:$A$105,E38,$B$6:$B$105))) | J38: =IF(E38="","",IF(F38="상상",N(I38),N(H38))) | K38: =IF(E38="","",COUNTIFS($F$6:$F$105,F38,$J$6:$J$105,">"&J38)+1)
C39: =IF(A39="","",IF(COUNTIF($A$6:$A$105,A39)>1,"번호 중복(한 번만 남기세요)",IF(COUNTIF(작품목록!$A$4:$A$103,A39)=0,"작품목록에 없는 번호",IF(ISNUMBER(B39),"","좋아요 수가 숫자가 아님")))) | E39: =IF(작품목록!A37="","",작품목록!A37) | F39: =IF(E39="","",작품목록!B37&"") | G39: =IF(E39="","",작품목록!G37&"") | H39: =IF(E39="","",IF(F39="상상","-",SUMIF($A$6:$A$105,E39,$B$6:$B$105))) | J39: =IF(E39="","",IF(F39="상상",N(I39),N(H39))) | K39: =IF(E39="","",COUNTIFS($F$6:$F$105,F39,$J$6:$J$105,">"&J39)+1)
C40: =IF(A40="","",IF(COUNTIF($A$6:$A$105,A40)>1,"번호 중복(한 번만 남기세요)",IF(COUNTIF(작품목록!$A$4:$A$103,A40)=0,"작품목록에 없는 번호",IF(ISNUMBER(B40),"","좋아요 수가 숫자가 아님")))) | E40: =IF(작품목록!A38="","",작품목록!A38) | F40: =IF(E40="","",작품목록!B38&"") | G40: =IF(E40="","",작품목록!G38&"") | H40: =IF(E40="","",IF(F40="상상","-",SUMIF($A$6:$A$105,E40,$B$6:$B$105))) | J40: =IF(E40="","",IF(F40="상상",N(I40),N(H40))) | K40: =IF(E40="","",COUNTIFS($F$6:$F$105,F40,$J$6:$J$105,">"&J40)+1)
C41: =IF(A41="","",IF(COUNTIF($A$6:$A$105,A41)>1,"번호 중복(한 번만 남기세요)",IF(COUNTIF(작품목록!$A$4:$A$103,A41)=0,"작품목록에 없는 번호",IF(ISNUMBER(B41),"","좋아요 수가 숫자가 아님")))) | E41: =IF(작품목록!A39="","",작품목록!A39) | F41: =IF(E41="","",작품목록!B39&"") | G41: =IF(E41="","",작품목록!G39&"") | H41: =IF(E41="","",IF(F41="상상","-",SUMIF($A$6:$A$105,E41,$B$6:$B$105))) | J41: =IF(E41="","",IF(F41="상상",N(I41),N(H41))) | K41: =IF(E41="","",COUNTIFS($F$6:$F$105,F41,$J$6:$J$105,">"&J41)+1)
... C105: =IF(A105="","",IF(COUNTIF($A$6:$A$105,A105)>1,"번호 중복(한 번만 남기세요)",IF(COUNTIF(작품목록!$A$4:$A$103,A105)=0,"작품목록에 없는 번호",IF(ISNUMBER(B105),"","좋아요 수가 숫자가 아님")))) | E105: =IF(작품목록!A103="","",작품목록!A103) | F105: =IF(E105="","",작품목록!B103&"") | G105: =IF(E105="","",작품목록!G103&"") | H105: =IF(E105="","",IF(F105="상상","-",SUMIF($A$6:$A$105,E105,$B$6:$B$105))) | J105: =IF(E105="","",IF(F105="상상",N(I105),N(H105))) | K105: =IF(E105="","",COUNTIFS($F$6:$F$105,F105,$J$6:$J$105,">"&J105)+1)

Sheet 학급별참여율
A1: 학급별 참여율 순위 (1~6학년 × 7반)
A2: B열 노란 칸에 학급 학생 수를 입력하세요. 참여 학생 수는 작품목록의 대표 학년반 + 팀원 학년반으로 자동 계산돼요(2인 팀은 두 학생 모두 각자 반으로 셈, 1~2학년 상상 활동지 포함).
A3: ① 학급별 참여 현황 (학생 수만 입력) | J3: ② 참여율 순위 TOP 10 (발표용, 자동)
A4: 학년반 | B4: 학생 수 (입력) | C4: 참여 학생 수 | D4: 참여율 | E4: 순위 | F4: 담임 알림 제출 수 (1~2학년) | G4: 확인 | H4: 정렬 번호 (자동) | J4: 순위 | K4: 학년반 | L4: 참여 학생 수 | M4: 학생 수 | N4: 참여율
A5: 1-1 | B5: 24 | C5: =COUNTIF(작품목록!$C$4:$C$103,A5)+COUNTIF(작품목록!$D$4:$D$103,A5) -> 1 | D5: =IF(N(B5)=0,"",ROUND(C5/B5,4)) -> 0.0417 | E5: =IF(D5="","",COUNTIFS($D$5:$D$46,">"&D5)+COUNTIFS($D$5:$D$46,D5,$C$5:$C$46,">"&C5)+1) -> 4 | F5: 1 | G5: =IF(AND(N(B5)=0,C5>0),"학생 수를 입력하세요",IF(AND(N(B5)>0,C5>N(B5)),"참여 학생 수가 학생 수보다 많아요",IF(F5="","",IF(N(F5)=C5,"일치","작품목록 확인(차이 "&(N(F5)-C5)&"명)")))) -> 일치 | H5: =IF(E5="","",E5+COUNTIF($E$5:E5,E5)-1) -> 4 | J5: =IFERROR(INDEX($E$5:$E$46,MATCH(1,$H$5:$H$46,0)),"") -> 1 | K5: =IFERROR(INDEX($A$5:$A$46,MATCH(1,$H$5:$H$46,0)),"") -> 4-2 | L5: =IFERROR(INDEX($C$5:$C$46,MATCH(1,$H$5:$H$46,0)),"") -> 2 | M5: =IFERROR(INDEX($B$5:$B$46,MATCH(1,$H$5:$H$46,0)),"") -> 25 | N5: =IFERROR(INDEX($D$5:$D$46,MATCH(1,$H$5:$H$46,0)),"") -> 0.08
A6: 1-2 | B6: 26 | C6: =COUNTIF(작품목록!$C$4:$C$103,A6)+COUNTIF(작품목록!$D$4:$D$103,A6) -> 1 | D6: =IF(N(B6)=0,"",ROUND(C6/B6,4)) -> 0.0385 | E6: =IF(D6="","",COUNTIFS($D$5:$D$46,">"&D6)+COUNTIFS($D$5:$D$46,D6,$C$5:$C$46,">"&C6)+1) -> 10 | G6: =IF(AND(N(B6)=0,C6>0),"학생 수를 입력하세요",IF(AND(N(B6)>0,C6>N(B6)),"참여 학생 수가 학생 수보다 많아요",IF(F6="","",IF(N(F6)=C6,"일치","작품목록 확인(차이 "&(N(F6)-C6)&"명)")))) | H6: =IF(E6="","",E6+COUNTIF($E$5:E6,E6)-1) -> 10 | J6: =IFERROR(INDEX($E$5:$E$46,MATCH(2,$H$5:$H$46,0)),"") -> 2 | K6: =IFERROR(INDEX($A$5:$A$46,MATCH(2,$H$5:$H$46,0)),"") -> 5-1 | L6: =IFERROR(INDEX($C$5:$C$46,MATCH(2,$H$5:$H$46,0)),"") -> 2 | M6: =IFERROR(INDEX($B$5:$B$46,MATCH(2,$H$5:$H$46,0)),"") -> 26 | N6: =IFERROR(INDEX($D$5:$D$46,MATCH(2,$H$5:$H$46,0)),"") -> 0.0769
A7: 1-3 | B7: 28 | C7: =COUNTIF(작품목록!$C$4:$C$103,A7)+COUNTIF(작품목록!$D$4:$D$103,A7) -> 1 | D7: =IF(N(B7)=0,"",ROUND(C7/B7,4)) -> 0.0357 | E7: =IF(D7="","",COUNTIFS($D$5:$D$46,">"&D7)+COUNTIFS($D$5:$D$46,D7,$C$5:$C$46,">"&C7)+1) -> 19 | G7: =IF(AND(N(B7)=0,C7>0),"학생 수를 입력하세요",IF(AND(N(B7)>0,C7>N(B7)),"참여 학생 수가 학생 수보다 많아요",IF(F7="","",IF(N(F7)=C7,"일치","작품목록 확인(차이 "&(N(F7)-C7)&"명)")))) | H7: =IF(E7="","",E7+COUNTIF($E$5:E7,E7)-1) -> 19 | J7: =IFERROR(INDEX($E$5:$E$46,MATCH(3,$H$5:$H$46,0)),"") -> 3 | K7: =IFERROR(INDEX($A$5:$A$46,MATCH(3,$H$5:$H$46,0)),"") -> 5-2 | L7: =IFERROR(INDEX($C$5:$C$46,MATCH(3,$H$5:$H$46,0)),"") -> 2 | M7: =IFERROR(INDEX($B$5:$B$46,MATCH(3,$H$5:$H$46,0)),"") -> 28 | N7: =IFERROR(INDEX($D$5:$D$46,MATCH(3,$H$5:$H$46,0)),"") -> 0.0714
A8: 1-4 | B8: 25 | C8: =COUNTIF(작품목록!$C$4:$C$103,A8)+COUNTIF(작품목록!$D$4:$D$103,A8) -> 0 | D8: =IF(N(B8)=0,"",ROUND(C8/B8,4)) -> 0 | E8: =IF(D8="","",COUNTIFS($D$5:$D$46,">"&D8)+COUNTIFS($D$5:$D$46,D8,$C$5:$C$46,">"&C8)+1) -> 25 | G8: =IF(AND(N(B8)=0,C8>0),"학생 수를 입력하세요",IF(AND(N(B8)>0,C8>N(B8)),"참여 학생 수가 학생 수보다 많아요",IF(F8="","",IF(N(F8)=C8,"일치","작품목록 확인(차이 "&(N(F8)-C8)&"명)")))) | H8: =IF(E8="","",E8+COUNTIF($E$5:E8,E8)-1) -> 25 | J8: =IFERROR(INDEX($E$5:$E$46,MATCH(4,$H$5:$H$46,0)),"") -> 4 | K8: =IFERROR(INDEX($A$5:$A$46,MATCH(4,$H$5:$H$46,0)),"") -> 1-1 | L8: =IFERROR(INDEX($C$5:$C$46,MATCH(4,$H$5:$H$46,0)),"") -> 1 | M8: =IFERROR(INDEX($B$5:$B$46,MATCH(4,$H$5:$H$46,0)),"") -> 24 | N8: =IFERROR(INDEX($D$5:$D$46,MATCH(4,$H$5:$H$46,0)),"") -> 0.0417
A9: 1-5 | B9: 27 | C9: =COUNTIF(작품목록!$C$4:$C$103,A9)+COUNTIF(작품목록!$D$4:$D$103,A9) -> 1 | D9: =IF(N(B9)=0,"",ROUND(C9/B9,4)) -> 0.037 | E9: =IF(D9="","",COUNTIFS($D$5:$D$46,">"&D9)+COUNTIFS($D$5:$D$46,D9,$C$5:$C$46,">"&C9)+1) -> 14 | G9: =IF(AND(N(B9)=0,C9>0),"학생 수를 입력하세요",IF(AND(N(B9)>0,C9>N(B9)),"참여 학생 수가 학생 수보다 많아요",IF(F9="","",IF(N(F9)=C9,"일치","작품목록 확인(차이 "&(N(F9)-C9)&"명)")))) | H9: =IF(E9="","",E9+COUNTIF($E$5:E9,E9)-1) -> 14 | J9: =IFERROR(INDEX($E$5:$E$46,MATCH(5,$H$5:$H$46,0)),"") -> 4 | K9: =IFERROR(INDEX($A$5:$A$46,MATCH(5,$H$5:$H$46,0)),"") -> 2-2 | L9: =IFERROR(INDEX($C$5:$C$46,MATCH(5,$H$5:$H$46,0)),"") -> 1 | M9: =IFERROR(INDEX($B$5:$B$46,MATCH(5,$H$5:$H$46,0)),"") -> 24 | N9: =IFERROR(INDEX($D$5:$D$46,MATCH(5,$H$5:$H$46,0)),"") -> 0.0417
A10: 1-6 | B10: 24 | C10: =COUNTIF(작품목록!$C$4:$C$103,A10)+COUNTIF(작품목록!$D$4:$D$103,A10) -> 0 | D10: =IF(N(B10)=0,"",ROUND(C10/B10,4)) -> 0 | E10: =IF(D10="","",COUNTIFS($D$5:$D$46,">"&D10)+COUNTIFS($D$5:$D$46,D10,$C$5:$C$46,">"&C10)+1) -> 25 | G10: =IF(AND(N(B10)=0,C10>0),"학생 수를 입력하세요",IF(AND(N(B10)>0,C10>N(B10)),"참여 학생 수가 학생 수보다 많아요",IF(F10="","",IF(N(F10)=C10,"일치","작품목록 확인(차이 "&(N(F10)-C10)&"명)")))) | H10: =IF(E10="","",E10+COUNTIF($E$5:E10,E10)-1) -> 26 | J10: =IFERROR(INDEX($E$5:$E$46,MATCH(6,$H$5:$H$46,0)),"") -> 4 | K10: =IFERROR(INDEX($A$5:$A$46,MATCH(6,$H$5:$H$46,0)),"") -> 6-1 | L10: =IFERROR(INDEX($C$5:$C$46,MATCH(6,$H$5:$H$46,0)),"") -> 1 | M10: =IFERROR(INDEX($B$5:$B$46,MATCH(6,$H$5:$H$46,0)),"") -> 24 | N10: =IFERROR(INDEX($D$5:$D$46,MATCH(6,$H$5:$H$46,0)),"") -> 0.0417
A11: 1-7 | B11: 26 | C11: =COUNTIF(작품목록!$C$4:$C$103,A11)+COUNTIF(작품목록!$D$4:$D$103,A11) -> 0 | D11: =IF(N(B11)=0,"",ROUND(C11/B11,4)) -> 0 | E11: =IF(D11="","",COUNTIFS($D$5:$D$46,">"&D11)+COUNTIFS($D$5:$D$46,D11,$C$5:$C$46,">"&C11)+1) -> 25 | G11: =IF(AND(N(B11)=0,C11>0),"학생 수를 입력하세요",IF(AND(N(B11)>0,C11>N(B11)),"참여 학생 수가 학생 수보다 많아요",IF(F11="","",IF(N(F11)=C11,"일치","작품목록 확인(차이 "&(N(F11)-C11)&"명)")))) | H11: =IF(E11="","",E11+COUNTIF($E$5:E11,E11)-1) -> 27 | J11: =IFERROR(INDEX($E$5:$E$46,MATCH(7,$H$5:$H$46,0)),"") -> 7 | K11: =IFERROR(INDEX($A$5:$A$46,MATCH(7,$H$5:$H$46,0)),"") -> 3-1 | L11: =IFERROR(INDEX($C$5:$C$46,MATCH(7,$H$5:$H$46,0)),"") -> 1 | M11: =IFERROR(INDEX($B$5:$B$46,MATCH(7,$H$5:$H$46,0)),"") -> 25 | N11: =IFERROR(INDEX($D$5:$D$46,MATCH(7,$H$5:$H$46,0)),"") -> 0.04
A12: 2-1 | B12: 27 | C12: =COUNTIF(작품목록!$C$4:$C$103,A12)+COUNTIF(작품목록!$D$4:$D$103,A12) -> 1 | D12: =IF(N(B12)=0,"",ROUND(C12/B12,4)) -> 0.037 | E12: =IF(D12="","",COUNTIFS($D$5:$D$46,">"&D12)+COUNTIFS($D$5:$D$46,D12,$C$5:$C$46,">"&C12)+1) -> 14 | F12: 1 | G12: =IF(AND(N(B12)=0,C12>0),"학생 수를 입력하세요",IF(AND(N(B12)>0,C12>N(B12)),"참여 학생 수가 학생 수보다 많아요",IF(F12="","",IF(N(F12)=C12,"일치","작품목록 확인(차이 "&(N(F12)-C12)&"명)")))) -> 일치 | H12: =IF(E12="","",E12+COUNTIF($E$5:E12,E12)-1) -> 15 | J12: =IFERROR(INDEX($E$5:$E$46,MATCH(8,$H$5:$H$46,0)),"") -> 7 | K12: =IFERROR(INDEX($A$5:$A$46,MATCH(8,$H$5:$H$46,0)),"") -> 5-3 | L12: =IFERROR(INDEX($C$5:$C$46,MATCH(8,$H$5:$H$46,0)),"") -> 1 | M12: =IFERROR(INDEX($B$5:$B$46,MATCH(8,$H$5:$H$46,0)),"") -> 25 | N12: =IFERROR(INDEX($D$5:$D$46,MATCH(8,$H$5:$H$46,0)),"") -> 0.04
A13: 2-2 | B13: 24 | C13: =COUNTIF(작품목록!$C$4:$C$103,A13)+COUNTIF(작품목록!$D$4:$D$103,A13) -> 1 | D13: =IF(N(B13)=0,"",ROUND(C13/B13,4)) -> 0.0417 | E13: =IF(D13="","",COUNTIFS($D$5:$D$46,">"&D13)+COUNTIFS($D$5:$D$46,D13,$C$5:$C$46,">"&C13)+1) -> 4 | G13: =IF(AND(N(B13)=0,C13>0),"학생 수를 입력하세요",IF(AND(N(B13)>0,C13>N(B13)),"참여 학생 수가 학생 수보다 많아요",IF(F13="","",IF(N(F13)=C13,"일치","작품목록 확인(차이 "&(N(F13)-C13)&"명)")))) | H13: =IF(E13="","",E13+COUNTIF($E$5:E13,E13)-1) -> 5 | J13: =IFERROR(INDEX($E$5:$E$46,MATCH(9,$H$5:$H$46,0)),"") -> 7 | K13: =IFERROR(INDEX($A$5:$A$46,MATCH(9,$H$5:$H$46,0)),"") -> 6-4 | L13: =IFERROR(INDEX($C$5:$C$46,MATCH(9,$H$5:$H$46,0)),"") -> 1 | M13: =IFERROR(INDEX($B$5:$B$46,MATCH(9,$H$5:$H$46,0)),"") -> 25 | N13: =IFERROR(INDEX($D$5:$D$46,MATCH(9,$H$5:$H$46,0)),"") -> 0.04
A14: 2-3 | B14: 26 | C14: =COUNTIF(작품목록!$C$4:$C$103,A14)+COUNTIF(작품목록!$D$4:$D$103,A14) -> 1 | D14: =IF(N(B14)=0,"",ROUND(C14/B14,4)) -> 0.0385 | E14: =IF(D14="","",COUNTIFS($D$5:$D$46,">"&D14)+COUNTIFS($D$5:$D$46,D14,$C$5:$C$46,">"&C14)+1) -> 10 | G14: =IF(AND(N(B14)=0,C14>0),"학생 수를 입력하세요",IF(AND(N(B14)>0,C14>N(B14)),"참여 학생 수가 학생 수보다 많아요",IF(F14="","",IF(N(F14)=C14,"일치","작품목록 확인(차이 "&(N(F14)-C14)&"명)")))) | H14: =IF(E14="","",E14+COUNTIF($E$5:E14,E14)-1) -> 11 | J14: =IFERROR(INDEX($E$5:$E$46,MATCH(10,$H$5:$H$46,0)),"") -> 10 | K14: =IFERROR(INDEX($A$5:$A$46,MATCH(10,$H$5:$H$46,0)),"") -> 1-2 | L14: =IFERROR(INDEX($C$5:$C$46,MATCH(10,$H$5:$H$46,0)),"") -> 1 | M14: =IFERROR(INDEX($B$5:$B$46,MATCH(10,$H$5:$H$46,0)),"") -> 26 | N14: =IFERROR(INDEX($D$5:$D$46,MATCH(10,$H$5:$H$46,0)),"") -> 0.0385
A15: 2-4 | B15: 28 | C15: =COUNTIF(작품목록!$C$4:$C$103,A15)+COUNTIF(작품목록!$D$4:$D$103,A15) -> 1 | D15: =IF(N(B15)=0,"",ROUND(C15/B15,4)) -> 0.0357 | E15: =IF(D15="","",COUNTIFS($D$5:$D$46,">"&D15)+COUNTIFS($D$5:$D$46,D15,$C$5:$C$46,">"&C15)+1) -> 19 | G15: =IF(AND(N(B15)=0,C15>0),"학생 수를 입력하세요",IF(AND(N(B15)>0,C15>N(B15)),"참여 학생 수가 학생 수보다 많아요",IF(F15="","",IF(N(F15)=C15,"일치","작품목록 확인(차이 "&(N(F15)-C15)&"명)")))) | H15: =IF(E15="","",E15+COUNTIF($E$5:E15,E15)-1) -> 20 | J15: ※ 같은 순위가 여러 반이면 학년반 순서로 이어서 보여 줘요. 참여율이 같으면 참여 학생 수가 많은 반이 위예요.
A16: 2-5 | B16: 25 | C16: =COUNTIF(작품목록!$C$4:$C$103,A16)+COUNTIF(작품목록!$D$4:$D$103,A16) -> 0 | D16: =IF(N(B16)=0,"",ROUND(C16/B16,4)) -> 0 | E16: =IF(D16="","",COUNTIFS($D$5:$D$46,">"&D16)+COUNTIFS($D$5:$D$46,D16,$C$5:$C$46,">"&C16)+1) -> 25 | G16: =IF(AND(N(B16)=0,C16>0),"학생 수를 입력하세요",IF(AND(N(B16)>0,C16>N(B16)),"참여 학생 수가 학생 수보다 많아요",IF(F16="","",IF(N(F16)=C16,"일치","작품목록 확인(차이 "&(N(F16)-C16)&"명)")))) | H16: =IF(E16="","",E16+COUNTIF($E$5:E16,E16)-1) -> 28
A17: 2-6 | B17: 27 | C17: =COUNTIF(작품목록!$C$4:$C$103,A17)+COUNTIF(작품목록!$D$4:$D$103,A17) -> 0 | D17: =IF(N(B17)=0,"",ROUND(C17/B17,4)) -> 0 | E17: =IF(D17="","",COUNTIFS($D$5:$D$46,">"&D17)+COUNTIFS($D$5:$D$46,D17,$C$5:$C$46,">"&C17)+1) -> 25 | G17: =IF(AND(N(B17)=0,C17>0),"학생 수를 입력하세요",IF(AND(N(B17)>0,C17>N(B17)),"참여 학생 수가 학생 수보다 많아요",IF(F17="","",IF(N(F17)=C17,"일치","작품목록 확인(차이 "&(N(F17)-C17)&"명)")))) | H17: =IF(E17="","",E17+COUNTIF($E$5:E17,E17)-1) -> 29 | J17: ③ 전교 합계 (자동)
A18: 2-7 | B18: 24 | C18: =COUNTIF(작품목록!$C$4:$C$103,A18)+COUNTIF(작품목록!$D$4:$D$103,A18) -> 0 | D18: =IF(N(B18)=0,"",ROUND(C18/B18,4)) -> 0 | E18: =IF(D18="","",COUNTIFS($D$5:$D$46,">"&D18)+COUNTIFS($D$5:$D$46,D18,$C$5:$C$46,">"&C18)+1) -> 25 | G18: =IF(AND(N(B18)=0,C18>0),"학생 수를 입력하세요",IF(AND(N(B18)>0,C18>N(B18)),"참여 학생 수가 학생 수보다 많아요",IF(F18="","",IF(N(F18)=C18,"일치","작품목록 확인(차이 "&(N(F18)-C18)&"명)")))) | H18: =IF(E18="","",E18+COUNTIF($E$5:E18,E18)-1) -> 30 | J18: 전교 학생 수 | L18: =SUM($B$5:$B$46) -> 1090
A19: 3-1 | B19: 25 | C19: =COUNTIF(작품목록!$C$4:$C$103,A19)+COUNTIF(작품목록!$D$4:$D$103,A19) -> 1 | D19: =IF(N(B19)=0,"",ROUND(C19/B19,4)) -> 0.04 | E19: =IF(D19="","",COUNTIFS($D$5:$D$46,">"&D19)+COUNTIFS($D$5:$D$46,D19,$C$5:$C$46,">"&C19)+1) -> 7 | F19: - | G19: =IF(AND(N(B19)=0,C19>0),"학생 수를 입력하세요",IF(AND(N(B19)>0,C19>N(B19)),"참여 학생 수가 학생 수보다 많아요","")) | H19: =IF(E19="","",E19+COUNTIF($E$5:E19,E19)-1) -> 7 | J19: 참여 학생 수 | L19: =SUM($C$5:$C$46) -> 27
